Workbook
Name 內部: 拆單用!$B$3:$B$39
Name 內部五金: 拆單用!$H$3:$H$7
Name 外部: 拆單用!$C$3:$C$58
Name 外部五金: 拆單用!$I$3:$I$80
Name 衣廚五金: 拆單用!$L$3:$L$27
Name 床架_臥塌: 拆單用!$G$3:$G$11
Name 其它五金: 拆單用!$K$3:$K$33
Name 和旺: 資料庫!$AJ$2:$AV$2
Name 抽屜: 拆單用!$D$3:$D$27
Name 抽屜五金: 拆單用!$J$3:$J$67
Name 抽盤: 拆單用!$F$3:$F$8
Name 抽盤_不見軌道: 拆單用!$F$3:$F$8
Name 抽箱: 拆單用!$E$3:$E$12
Name 科定: 資料庫!$AJ$3:$AV$3
Name 桶身: 拆單用!$A$3:$A$38

Sheet 客戶資料
A3: 1 | C3: 2 | D3: 3 | E3: 4 | F3: 5 | G3: 6 | H3: 7 | I3: 8 | J3: 9 | K3: 10 | L3: 11 | M3: 12 | N3: 13 | O3: 14 | P3: 15
Q4: 有無附上名片 | R4: 目錄盒
R5: 索取日期 | S5: 數量
A6: 設計師/業務 | B6: 客戶編號 | C6: 聯絡電話 | D6: 公司名稱 | E6: 統編 | F6: 公司地址 | G6: 公司電話 | H6: 切口金額 | I6: 切口餘額 | J6: 板材折數 | K6: 安裝折數 | O6: 登入日期 | P6: 客戶編號
B7: 員工
A8: 和旺系統櫃 | B8: AA0A000 | E8: 90019206 | F8: 新北市樹林區樹新路183巷13號1樓 | J8: 0 | O8: 44932 | P8: =#REF! -> #REF!
A9: 吳冠裕(冠鈺工程行) | B9: AA0B001 | C9: 0921122053 | D9: 冠鈺工程行 | E9: 85178554 | F9: 新北市樹林區樹新路183巷13號1樓 | J9: 0.41 | K9: 0.2 | O9: 44932 | P9: =#REF! -> #REF! | R9: 44961 | S9: 1
A10: 劉軒魁 | B10: AA0B002 | C10: 0953085789 | F10: 新北市新莊區民本街53巷27號2樓 | J10: 0.41 | K10: =K9 -> 0.2 | O10: 44932 | P10: =#REF! -> #REF!
A11: 周呈勳(泰丞水電) | B11: AA0B003 | C11: 0958377085 | J11: 0.41 | K11: =K10 -> 0.2 | O11: 44932 | P11: =#REF! -> #REF! | R11: 112/2/3 | S11: 3
A12: 李嘉欣(尚鋐電器) | B12: AA0B004 | C12: 0922338900 | D12: 尚鋐電氣行 | E12: 31709514 | F12: 新北市新莊區青山路一段8號之11樓 | J12: 0.41 | K12: =K11 -> 0.2 | O12: 44932 | P12: =#REF! -> #REF!
A13: 張家祥 | B13: AA0C011 | J13: 0.41 | K13: =K12 -> 0.2 | O13: 44932 | P13: =#REF! -> #REF!
A14: 吳心彤 | B14: AA0D001 | C14: 0928220353 | O14: 44932 | P14: =#REF! -> #REF!
A15: 陳昱廷 | B15: AA0D002 | P15: =#REF! -> #REF!
B16: AA0D003 | P16: =#REF! -> #REF!
P17: =#REF! -> #REF!
P18: =#REF! -> #REF!
P19: =#REF! -> #REF!
B21: 設計公司
A22: 柳震東(沐晨) | B22: BA0001 | C22: 0920199706 | D22: 沐晨室內裝修有限公司 | E22: 55769700 | F22: 台北市中山區八德路二段172號1樓 | J22: 0.6 | K22: 0.2 | O22: 44866 | P22: =#REF! -> #REF! | R22: 112/2/15 | S22: 1
A23: 秦怡婷(光漫) | B23: BA0002 | C23: 0987754669 | D23: 龍英室內裝修設計工程有限公司 | E23: 16398173 | F23: 台北市中山區民生東路一段87號6樓 | J23: 0.45 | K23: =K22 -> 0.2 | O23: 44939 | P23: =#REF! -> #REF! | R23: 112/3/12 | S23: 1
A24: 廖哲民拉斐爾) | B24: BA0003 | C24: 0955286630 | D24: 拉斐爾空間設計企業社 | E24: 41408777 | F24: 新北市板橋區金華街10巷48弄70號4樓 | J24: 0.41 | K24: =K23 -> 0.2 | O24: 44939 | P24: =#REF! -> #REF!
A25: 胡君維(和慕) | B25: BA0004 | C25: 0980260704 | D25: 和慕空間設計 | J25: 0.49 | K25: =K24 -> 0.2 | O25: 44958 | P25: =#REF! -> #REF! | R25: 112/2/15 | S25: 1
A26: 賴德修(山門) | B26: BA0005 | C26: 0903073307 | D26: 山門綠建材 | E26: 58336518 | F26: 宜蘭縣宜蘭市文化里民族路310號7樓 | J26: 0.49 | K26: =K25 -> 0.2 | O26: 44958 | P26: =#REF! -> #REF! | R26: 112/2/16 | S26: 1
A27: 彭思亮(豐達) | B27: BA0006 | C27: 0988598615 | D27: 豐達室內裝修設計有限公司 | E27: 80305291 | F27: 台北市民生東路五段85號2樓 | J27: 0.49 | K27: =K26 -> 0.2 | O27: 44977 | P27: =#REF! -> #REF! | R27: 112/2/20 | S27: 1
A28: 陳昭宇 | B28: BA0007 | J28: 0.49 | K28: =K27 -> 0.2 | O28: 44977 | P28: =#REF! -> #REF! | R28: 112/2/10 | S28: 1
A29: 張修睿 | B29: BA0008 | C29: 0954154359 | D29: 从彡設計 | F29: 台北市信義區基隆一段141號13樓之3 | J29: 0.49 | K29: =K28 -> 0.2 | O29: 44977 | P29: =#REF! -> #REF! | R29: 112/3/5 | S29: 1
A30: 溫培堯 | B30: BA0009 | C30: 0931657652 | D30: 川墨室內設計 | F30: 台中市 | J30: 0.49 | K30: =K29 -> 0.2 | O30: 44977 | P30: =#REF! -> #REF! | R30: 112/2/14 | S30: 1
A31: 胡逸軒 | B31: BA0010 | C31: 0925727388 | D31: 或設計有限公司 | E31: 66603930 | F31: 新北市汐止區新台五路一段86號15樓 | J31: 0.49 | K31: 0.2 | O31: 44998 | P31: =#REF! -> #REF! | R31: 112/3/26 | S31: 1
A32: 林采郁 | B32: BA0011 | C32: 0981127720 | D32: 菲朵空間設計 | F32: 新北市土城區立雲街5巷10號1樓 | J32: 0.49 | K32: 0.2 | O32: 45011 | P32: =#REF! -> #REF!
B33: BA0012 | P33: =#REF! -> #REF!
B34: BA0013 | P34: =#REF! -> #REF!
B35: BA0014 | P35: =#REF! -> #REF!
B36: BA0015 | P36: =#REF! -> #REF!
B37: BA0016 | P37: =#REF! -> #REF!
B38: BA0017 | P38: =#REF! -> #REF!
B39: BA0018 | P39: =#REF! -> #REF!
B40: BA0019 | P40: =#REF! -> #REF!
B41: BA0020 | P41: =#REF! -> #REF!
B42: BA0021 | P42: =#REF! -> #REF!
B43: BA0022 | P43: =#REF! -> #REF!
...

Sheet 廠商資料
A1: 廠商名稱 | B1: 業務員 | C1: 公司資料
C2: 公司名稱 | D2: 統編 | E2: 登記地址 | F2: 工廠(店家)地址 | G2: 電話
A3: 李安
A4: 達思 | C4: 達思企業有限公司 | D4: 42574942 | E4: 桃園市龜山區復興街永樂巷36弄15號
A5: 積甲 | C5: 積甲系統生活空間有限公司 | D5: 50883560 | E5: 台北市士林區延平北路5段197巷9號1樓
A6: 九江 | C6: 九江五金行 | D6: 04568218 | E6: 台北市萬華區西寧南路233號1樓
A7: 昊川 | C7: 寧津縣昊川機械有限公司 | E7: 中華人民共合國山東省德州市寧津縣寧城街道辦事處八里堂村 | G7: +86 18553415459
A8: 嘉慷 | C8: 嘉慷五金行 | D8: 78186426 | E8: 新北市新莊區民安西路110號1樓 | G8: 02-22051026
A9: 建泰

Sheet 資料庫
A1: 櫃號 | B1: 櫃體 名稱 | C1: 產品名稱 | D1: 代號 | E1: 開板尺寸 | J1: 生產 數量 | K1: 板材 基材 | L1: 板材 廠商選項 | M1: 板材 廠商 | N1: 原廠 色號 | O1: 原廠 板材名稱 | P1: 和旺編碼 板材色號 | Q1: 色號 板名 | R1: 板材 廠商 | S1: 封邊條 廠商 | T1: 封邊條色號 | V1: 修補筆 廠商 | W1: 修補筆色號 | Z1: 標記 | AA1: 計價 單位 | AC1: 五金 配件 | AD1: 規格 | AE1: 門板 加工 | AF1: 規格 | AG1: 五金配 件牌價 | AH1: 門板加工 牌價 | AI1: 板材 牌價 | AJ1: 備註 | AK1: 特殊 加工 | AL1: 計價 單位 | AM1: 狀態 | AN1: 狀態代碼
E2: 長 | F2: 封邊 | G2: 寬 | H2: 封邊 | I2: 厚
N3: DC | O3: 雙色 | P3: DC | Q3: 雙色 | AM3: 新增 | AN3: A
A4: 1 | C4: 頂板 | F4: A | H4: A | I4: 4 | J4: 1 | K4: 木芯板 | L4: 百順 | M4: 百益 | N4: K101 | O4: 珍珠白發泡板 | P4: K101 | Q4: 珍珠白發泡板 | R4: 百益 | Z4: 背板溝 | AA4: 才 | AC4: w0 | AE4: 門片/抽頭斜把(限17mm板) | AF4: 公分 | AH4: 20 | AI4: 310 | AJ4: 需另加以上系列價格 | AL4: 個 | AM4: 補料 | AN4: B
A5: =A4+1 -> 2 | C5: 底板 | F5: AA | H5: AA | I5: 8 | J5: =J4+1 -> 2 | K5: 發泡板 | L5: 和旺 | O5: 發泡板 | P5: 9999 | Q5: 發泡板 | Z5: 背板溝 面開槽 | AA5: 片 | AC5: w1 | AE5: 門片/抽頭打型(限17mm板) | AF5: 才 | AH5: 540 | AI5: 310 | AJ5: 需另加以上系列價格 | AL5: 個 | AM5: 追加 | AN5: N
A6: =A5+1 -> 3 | C6: 左側板 | F6: AP | H6: AP | I6: 17 | J6: =J5+1 -> 3 | K6: 密迪板 | L6: 科定 | O6: 發泡板 | P6: Z1001 | Q6: 凡爾賽橡木 | Z6: 背板溝 側開槽 | AA6: 支 | AC6: w2 | AE6: 門片/抽頭Z把(限17mm板) | AF6: 公分 | AH6: 30 | AI6: 310 | AJ6: 需另加以上系列價格 | AL6: 個 | AM6: 外加工 | AN6: W
A7: =A6+1 -> 4 | C7: 右側板 | F7: PP | H7: PP | I7: 18 | J7: =J6+1 -> 4 | K7: PP皮板 | L7: 板橋木業 | M7: 百順 | N7: POLY | P7: BA0001 | Q7: 純白 | R7: 百順 | S7: 達思企業 | T7: SF9084C | U7: KM448C | V7: 達思企業 | W7: K37718 | Z7: 背板溝 兩向開槽 | AA7: 組 | AC7: w3 | AE7: 代挖埋入式把手 | AF7: 孔 | AH7: 60 | AI7: 310 | AJ7: 實價 | AL7: 個 | AM7: 外包 | AN7: O
A8: =A7+1 -> 5 | C8: 背板 | F8: P | H8: P | I8: 20 | J8: =J7+1 -> 5 | K8: 實木皮板 | L8: 一品 | M8: 李安 | N8: 臻木系列 | O8: 迎幸 | P8: V404-0 | Q8: 迎幸 | R8: 李安 | S8: 達思企業 | T8: SF9081C | V8: 達思企業 | W8: KMF278 | X8: JL3319 | Z8: 背板 | AA8: 米 | AC8: w4 | AI8: 300 | AL8: 個 | AM8: 修改 | AN8: F
A9: =A8+1 -> 6 | C9: 背拉桿 | I9: 23 | J9: =J8+1 -> 6 | M9: 李安 | N9: 臻木系列 | O9: 水洗灰橡 | P9: V404-1 | Q9: 水洗灰橡 | R9: 李安 | S9: 達思企業 | T9: AD1187C | U9: SF9083C | V9: 達思企業 | Z9: 背板溝 排孔 | AC9: Cabineo 12 | AI9: 300 | AL9: 組 | AM9: 重出 | AN9: R
A10: =A9+1 -> 7 | C10: 踢腳板 | I10: 34 | J10: =J9+1 -> 7 | M10: 李安 | N10: 臻木系列 | O10: 典藏胡桃 | P10: V404-2 | Q10: 典藏胡桃 | R10: 李安 | S10: 達思企業 | T10: HL83352 | V10: 達思企業 | Z10: 排孔 | AC10: Cabineo 8 | AE10: 另貼其它3mm木皮 | AF10: 才 | AI10: 300 | AL10: 組 | AM10: 外購 | AN10: P
A11: =A10+1 -> 8 | C11: 固隔 | I11: 40 | J11: =J10+1 -> 8 | M11: 李安 | O11: 莫蘭迪奶茶 | P11: V404-3 | Q11: 莫蘭迪奶茶 | R11: 李安 | S11: 達思企業 | T11: AD1185C | V11: 達思企業 | Z11: 背板溝 面開槽 排孔 | AC11: Clamex P-15 | AE11: 鋁框拉門 | AF11: 才 | AG11: 100 | AI11: 300 | AL11: 組
A12: =A11+1 -> 9 | C12: 固隔(退) | I12: 51 | J12: =J11+1 -> 9 | M12: 李安 | N12: 3301 | O12: 北美原橡 | P12: 3301 | Q12: 北美原橡 | R12: 李安 | S12: 達思企業 | T12: K37769C | V12: 達思企業 | Z12: 背板溝 側開槽 排孔 | AC12: Clamex P-14 | AG12: 100 | AI12: 300 | AL12: 組
A13: =A12+1 -> 10 | C13: 活隔 | J13: =J12+1 -> 10 | M13: 李安 | N13: 3302 | O13: 鋸齒凡爾賽 | P13: 3302 | Q13: 鋸齒凡爾賽 | R13: 李安 | S13: 達思企業 | T13: R5622C | V13: 達思企業 | Z13: 背板溝 兩向開槽 排孔 | AC13: Clamex P-10 | AG13: 100 | AI13: 300 | AL13: 組
A14: =A13+1 -> 11 | C14: 左門板 | J14: =J13+1 -> 11 | M14: 李安 | N14: 3304 | O14: 鋸齒棕橡 | P14: 3304 | Q14: 鋸齒棕橡 | R14: 李安 | S14: 達思企業 | T14: JM266C | V14: 達思企業 | W14: K37859 | Z14: 面開槽 | AC14: Clamex P-15/10 | AG14: 100 | AI14: 300 | AL14: 組
A15: =A14+1 -> 12 | C15: 右門板 | J15: =J14+1 -> 12 | M15: 李安 | N15: 3305 | O15: 鋸齒胡桃 | P15: 3305 | Q15: 鋸齒胡桃 | R15: 李安 | S15: 達思企業 | T15: L0727C | V15: 達思企業 | W15: K37854 | Z15: 面開槽 排孔 | AC15: Clamex P-14 Flexus 連接件 | AG15: 100 | AI15: 300 | AL15: 組
A16: =A15+1 -> 13 | C16: 門板 | J16: =J15+1 -> 13 | M16: 李安 | N16: V320-1 | O16: 水染白橡 | P16: V320-1 | Q16: 水染白橡 | R16: 李安 | S16: 達思企業 | T16: L3260WC | V16: 達思企業 | W16: L3260 | Z16: 側開槽 排孔 | AC16: Bisco P14 連接件 | AG16: 100 | AI16: 300 | AL16: 組
A17: =A16+1 -> 14 | C17: 中立板 | J17: =J16+1 -> 14 | M17: 李安 | N17: V320-2 | O17: 水洗粉橡 | P17: V320-2 | Q17: 水洗粉橡 | R17: 李安 | S17: 達思企業 | T17: K4757C | V17: 達思企業 | W17: L3575 | Z17: 側開槽 單邊排孔 | AC17: Bisco P10 連接件 | AI17: 300 | AL17: 組
A18: =A17+1 -> 15 | C18: 中立板(退) | J18: =J17+1 -> 15 | M18: 李安 | N18: V320-4 | O18: 水洗紅橡 | P18: V320-4 | Q18: 水洗紅橡 | R18: 李安 | S18: 達思企業 | T18: SF8975C | V18: 達思企業 | W18: K4005 | Z18: 側開槽 | AC18: Tenso P-14 卡扣式連接件 | AI18: 350 | AL18: 組
A19: =A18+1 -> 16 | C19: 抽頭 | J19: =J18+1 -> 16 | M19: 李安 | N19: V320-5 | O19: 水染胡桃 | P19: V320-5 | Q19: 水染胡桃 | R19: 李安 | S19: 達思企業 | T19: 75753C | V19: 達思企業 | W19: HB180 | Z19: 面、側開槽 | AC19: Tenso P-10 卡扣式連接件 | AI19: 420 | AJ19: =CONCATENATE(P30,Q30) -> V313-3檜木 | AK19: 270 | AL19: 組
A20: =A19+1 -> 17 | C20: 左抽牆 | J20: =J19+1 -> 17 | M20: 李安 | N20: V320-8 | O20: 京都栓木 | P20: V320-8 | Q20: 京都栓木 | R20: 李安 | S20: 達思企業 | T20: R4262C | U20: 75753C | V20: 達思企業 | W20: K31957 | Z20: 絞鏈孔 | AC20: Divario P-18 連接件 | AI20: 420 | AJ20: =CONCATENATE(P31,Q31) -> V313-2紅粉佳人 | AK20: 270 | AL20: 組
A21: =A20+1 -> 18 | C21: 右抽牆 | J21: =J20+1 -> 18 | M21: 李安 | N21: V3143 | O21: 摩卡橡木 | P21: V3143 | Q21: 摩卡橡木 | R21: 李安 | S21: 達思企業 | T21: SF9081C | V21: 達思企業 | W21: SF9930 | Z21: 絞鏈孔 下孔上升1公分 | AC21: 30公分三節式緩衝滑軌(非重型) | AD21: 30 | AG21: 1000 | AI21: 420 | AJ21: =CONCATENATE(P32,Q32) -> V313-1白橡 | AK21: 270 | AL21: 組
A22: =A21+1 -> 19 | C22: 前抽牆 | J22: =J21+1 -> 19 | M22: 李安 | N22: V3142 | O22: 黑桃 | P22: V3142 | Q22: 黑桃 | R22: 李安 | S22: 達思企業 | T22: JM1424C | V22: 達思企業 | W22: K306 | Z22: 絞鏈孔 下孔上升15公分 | AC22: 35公分三節式緩衝滑軌(非重型) | AD22: 35 | AG22: 1000 | AI22: 420 | AJ22: =CONCATENATE(P33,Q33) -> V313-0白木紋 | AK22: 270 | AL22: 組
A23: =A22+1 -> 20 | C23: 後抽牆 | J23: =J22+1 -> 20 | M23: 李安 | N23: V3141 | O23: 胡桃 | P23: V3141 | Q23: 胡桃 | R23: 李安 | S23: 達思企業 | T23: AD5033C | V23: 達思企業 | W23: K37769 | X23: K37854 | Y23: K306 | Z23: 絞鏈孔 外把手 | AC23: 40公分三節式緩衝滑軌(非重型) | AD23: 40 | AG23: 1000 | AI23: 420 | AJ23: =CONCATENATE(P43,Q43) -> P8716砂面淺灰 | AK23: 270 | AL23: 組
A24: =A23+1 -> 21 | C24: 抽底 | J24: =J23+1 -> 21 | M24: 李安 | N24: V313-9 | O24: 黑木紋 | P24: V313-9 | Q24: 黑木紋 | R24: 李安 | S24: 達思企業 | T24: AD1185C | V24: 達思企業 | W24: AD1185 | Z24: 絞鏈孔 嵌把手 | AC24: 45公分三節式緩衝滑軌(非重型) | AD24: 45 | AG24: 1000 | AI24: 420 | AJ24: =CONCATENATE(P46,Q46) -> P8719砂面銅灰 | AK24: 270 | AL24: 組
A25: =A24+1 -> 22 | C25: 上前拉桿 | J25: =J24+1 -> 22 | M25: 李安 | N25: V313-8 | O25: 灰銀狐 | P25: V313-8 | Q25: 灰銀狐 | R25: 李安 | S25: 達思企業 | T25: JM201H2C | V25: 達思企業 | W25: 952 | Z25: 絞鏈孔 打型 | AC25: 50公分三節式緩衝滑軌(非重型) | AD25: 50 | AG25: 1000 | AI25: 420 | AJ25: =CONCATENATE(P66,Q66) -> P8752鏽斑栗咖 | AK25: 270 | AL25: 組
A26: =A25+1 -> 23 | C26: 下前拉桿 | J26: =J25+1 -> 23 | M26: 李安 | N26: V313-7 | O26: 清水模 | P26: V313-7 | Q26: 清水模 | R26: 李安 | Z26: 挖\絞鏈孔 斜把 | AC26: 55公分三節式緩衝滑軌(非重型) | AD26: 55 | AG26: 1250 | AI26: 420 | AJ26: =CONCATENATE(P67,Q67) -> P8753卡其荔枝紋 | AK26: 290 | AL26: 組
A27: =A26+1 -> 24 | C27: 上後拉桿 | J27: =J26+1 -> 24 | M27: 李安 | N27: V313-6 | O27: 肯柚 | P27: V313-6 | Q27: 肯柚 | R27: 李安 | Z27: 打型 | AC27: 60公分三節式緩衝滑軌(非重型) | AD27: 60 | AG27: 1250 | AI27: 420 | AJ27: =CONCATENATE(P68,Q68) -> P8005膚感鈦銀 | AK27: 290 | AL27: 組
A28: =A27+1 -> 25 | C28: 下後拉桿 | J28: =J27+1 -> 25 | M28: 李安 | N28: V313-5 | O28: 鋸齒柚木 | P28: V313-5 | Q28: 鋸齒柚木 | R28: 李安 | Z28: 上斜把手 | AC28: 長調整腳(公頭) | AD28: 長 | AI28: 440 | AJ28: =CONCATENATE(P82,Q82) -> P8018膚感栗咖 | AK28: 290 | AL28: 組
A29: =A28+1 -> 26 | C29: 左側落板 | J29: =J28+1 -> 26 | M29: 李安 | N29: V313-4 | O29: 紫羅蘭 | P29: V313-4 | Q29: 紫羅蘭 | R29: 李安 | Z29: 絞鏈孔 上斜把手 | AC29: 中調整腳(公頭) | AD29: 中 | AI29: 440 | AJ29: =CONCATENATE(P83,Q83) -> P8019膚感墨黑 | AL29: 組
A30: =A29+1 -> 27 | C30: 右側落板 | J30: =J29+1 -> 27 | M30: 李安 | N30: V313-3 | O30: 檜木 | P30: V313-3 | Q30: 檜木 | R30: 李安 | Z30: 下斜把手 | AC30: 短調整腳(公頭) | AD30: 短 | AG30: 50 | AI30: 440 | AJ30: =CONCATENATE(P84,Q84) -> P8020膚感灰綠 | AL30: 組
A31: =A30+1 -> 28 | C31: 外蓋背板 | J31: =J30+1 -> 28 | M31: 李安 | N31: V313-2 | O31: 紅粉佳人 | P31: V313-2 | Q31: 紅粉佳人 | R31: 李安 | Z31: 絞鏈孔 下斜把手 | AC31: 調整腳(母頭) | AJ31: =CONCATENATE(P85,Q85) -> P8021膚感黃褐
A32: =A31+1 -> 29 | C32: 內柱背板 | J32: =J31+1 -> 29 | M32: 李安 | N32: V313-1 | O32: 白橡 | P32: V313-1 | Q32: 白橡 | R32: 李安 | Z32: 側斜把手 | AC32: 緩衝鉸鏈(blun) 六分 | AD32: 6分 | AG32: 380 | AJ32: =CONCATENATE(P86,Q86) -> P8022膚感鐵灰 | AL32: 顆
A33: =A32+1 -> 30 | C33: 壁板 | J33: =J32+1 -> 30 | M33: 李安 | N33: V313-0 | O33: 白木紋 | P33: V313-0 | Q33: 白木紋 | R33: 李安 | Z33: 絞鏈孔 側斜把手 | AC33: 緩衝鉸鏈(blun) 三分 | AD33: 3分 | AG33: 380 | AJ33: =CONCATENATE(P87,Q87) -> P8023膚感米金 | AL33: 顆
A34: =A33+1 -> 31 | C34: 桌板 | J34: =J33+1 -> 31 | M34: 李安 | N34: V801-0 | O34: 結晶面板（白色） | P34: V801-0 | Q34: 結晶面板（白色） | R34: 李安 | Z34: 外把手 | AC34: 緩衝鉸鏈(blun) 入柱 | AD34: 入柱 | AJ34: =CONCATENATE(P88,Q88) -> P8404膚感杏灰 | AL34: 顆
A35: =A34+1 -> 32 | C35: 台面 | J35: =J34+1 -> 32 | M35: 板橋木業 | N35: A53 | O35: 埃及亞麻織 | P35: A53 | Q35: 埃及亞麻織 | R35: 板橋木業 | Z35: 崁把手 | AC35: 緩衝鉸鏈(blun) 負90度 | AD35: 負90度 | AJ35: =CONCATENATE(P89,Q89) -> P8305膚感卡其 | AL35: 顆
A36: =A35+1 -> 33 | C36: 床板 | J36: =J35+1 -> 33 | M36: 科定 | N36: P8706F | O36: 栗灰珍珠紋 | P36: P8709 | Q36: 栗灰珍珠紋 | R36: 科定 | Z36: 挖孔 下凸取手 | AC36: 緩衝鉸鏈(blun) 180度 | AD36: 180度 | AJ36: =CONCATENATE(P90,Q90) -> P8409膚感米灰 | AL36: 顆
A37: =A36+1 -> 34 | C37: 左右側板 | J37: =J36+1 -> 34 | M37: 科定 | N37: P8709F | O37: 墨黑珍珠紋 | P37: P8710 | Q37: 墨黑珍珠紋 | R37: 科定 | Z37: 三向開槽 | AC37: 緩衝鉸鏈(blun)厚門板用 六分 | AD37: 6分 | AG37: 450 | AJ37: =CONCATENATE(P91,Q91) -> P8024膚感黑雲石 | AL37: 顆
A38: =A37+1 -> 35 | C38: 頂底板 | J38: =J37+1 -> 35 | M38: 科定 | N38: P8705F | O38: 卡其珍珠紋 | P38: P8711 | Q38: 奶茶 | R38: 科定 | Z38: 四向開槽 | AC38: 緩衝鉸鏈(blun)厚門板用 三分 | AD38: 3分 | AG38: 450 | AJ38: =CONCATENATE(P92,Q92) -> P7320玻瑰金髮絲紋 | AL38: 顆
C39: 前側板 | J39: =J38+1 -> 36 | M39: 科定 | N39: P8702F | O39: 雪白珍珠紋 | P39: P8712 | Q39: 白雪 | R39: 科定 | Z39: 注意圖面 | AC39: 緩衝鉸鏈(blun)厚門板用 入柱 | AD39: 入柱 | AG39: 450 | AJ39: =CONCATENATE(P93,Q93) -> P7321黃銅髮絲紋 | AL39: 顆
C40: 後側板 | J40: =J39+1 -> 37 | M40: 科定 | N40: P8040C | O40: 砂面霧藍 | P40: P8713 | Q40: 砂面藍 | R40: 科定 | Z40: 同紋 | AC40: 緩衝鉸鏈(blun)厚門板用 負90度 | AD40: 負90度 | AL40: 顆
...

Sheet 五金配件
A1: 經辦業務 | B1: 業務員 | C1: 廠商名稱 | D1: 產品名稱(廠牌) | E1: 廠商目錄型號 | F1: 規格 | I1: 進貨單位 | J1: 銷貨單位 | K1: 備註 | L1: 牌價金額 | M1: 進貨金額 | N1: 進貨日期 | O1: 進貨數量 | P1: 退貨數量 | Q1: 傳票編號 | R1: 銷貨日期 | S1: 銷貨數量 | T1: 退貨數量 | U1: 銷貨案場 | V1: 傳票編號
F2: 長H x 寬W x 深D (公分)
A3: 吳冠裕 | B3: 張家銘 | C3: 拉米諾 | D3: w0 | I3: 箱(1000/組) | J3: 組
A4: 吳冠裕 | B4: 張家銘 | C4: 拉米諾 | D4: w1 | I4: 箱(1000/組) | J4: 組
A5: 吳冠裕 | B5: 張家銘 | C5: 拉米諾 | D5: w2 | I5: 箱(1000/組) | J5: 組
A6: 吳冠裕 | B6: 張家銘 | C6: 拉米諾 | D6: w3 | I6: 箱(1000/組) | J6: 組
A7: 吳冠裕 | B7: 張家銘 | C7: 拉米諾 | D7: w4 | I7: 箱(1000/組) | J7: 組
A8: 吳冠裕 | B8: 張家銘 | C8: 拉米諾 | D8: Cabineo 12 | I8: 箱(1000/組) | J8: 組
A9: 吳冠裕 | B9: 張家銘 | C9: 拉米諾 | D9: Cabineo 8 | I9: 箱(1000/組) | J9: 組
A10: 吳冠裕 | B10: 張家銘 | C10: 拉米諾 | D10: Clamex P-15 | I10: 箱(1000/組) | J10: 組
A11: 吳冠裕 | B11: 張家銘 | C11: 拉米諾 | D11: Clamex P-14 | I11: 箱(1000/組) | J11: 組
A12: 吳冠裕 | B12: 張家銘 | C12: 拉米諾 | D12: Clamex P-10 | I12: 箱(1000/組) | J12: 組
A13: 吳冠裕 | B13: 張家銘 | C13: 拉米諾 | D13: Clamex P-15/10 | I13: 箱(1000/組) | J13: 組
A14: 吳冠裕 | B14: 張家銘 | C14: 拉米諾 | D14: Clamex P-14 Flexus 連接件 | I14: 箱(1000/組) | J14: 組
... A22: 吳冠裕 | B22: 張家銘 | C22: 拉米諾 | D22: Divario P-18 連接件 | I22: 箱(1000/組) | J22: 組
A23: 劉軒魁 | C23: 積甲 | D23: 三節式緩衝滑軌(非重型) | F23: 30 | I23: 箱(15/組) | J23: 組
A24: 劉軒魁 | C24: 積甲 | D24: 三節式緩衝滑軌(非重型) | F24: 35 | I24: 箱(15/組) | J24: 組
A25: 劉軒魁 | C25: 積甲 | D25: 三節式緩衝滑軌(非重型) | F25: 40 | I25: 箱(15/組) | J25: 組
A26: 劉軒魁 | C26: 積甲 | D26: 三節式緩衝滑軌(非重型) | F26: 45 | I26: 箱(15/組) | J26: 組
A27: 劉軒魁 | C27: 積甲 | D27: 三節式緩衝滑軌(非重型) | F27: 50 | I27: 箱(15/組) | J27: 組
A28: 劉軒魁 | C28: 積甲 | D28: 三節式緩衝滑軌(非重型) | F28: 55 | I28: 箱(15/組) | J28: 組
A29: 劉軒魁 | C29: 積甲 | D29: 三節式緩衝滑軌(非重型) | F29: 60 | I29: 箱(15/組) | J29: 組 | K29: 含母頭
A30: 劉軒魁 | C30: 積甲 | D30: 調整腳(公頭) | F30: 長 | I30: 袋(100/顆) | J30: 組 | K30: 含母頭
A31: 劉軒魁 | C31: 積甲 | D31: 調整腳(公頭) | F31: 中 | I31: 袋(100/顆) | J31: 組 | K31: 含母頭
A32: 劉軒魁 | C32: 積甲 | D32: 調整腳(公頭) | F32: 短 | I32: 袋(100/顆) | J32: 組 | K32: 含母頭
A33: 劉軒魁 | C33: 積甲 | D33: 調整腳(母頭) | I33: 袋(300/顆)
A34: 劉軒魁 | C34: 積甲 | D34: 緩衝鉸鏈(blun) | F34: 6分 | I34: 箱
A35: 劉軒魁 | C35: 積甲 | D35: 緩衝鉸鏈(blun) | F35: 3分 | I35: 箱
A36: 劉軒魁 | C36: 積甲 | D36: 緩衝鉸鏈(blun) | F36: 入柱 | I36: 箱
A37: 劉軒魁 | C37: 積甲 | D37: 緩衝鉸鏈(blun) | F37: 負90度 | I37: 箱
A38: 劉軒魁 | C38: 積甲 | D38: 緩衝鉸鏈(blun) | F38: 180度 | I38: 箱
A39: 吳冠裕 | C39: 建泰 | D39: 緩衝鉸鏈(blun)厚門板用 | F39: 6分 | I39: 箱
D40: 緩衝鉸鏈(blun)厚門板用 | F40: 3分 | I40: 箱
D41: 緩衝鉸鏈(blun)厚門板用 | F41: 入柱 | I41: 箱
D42: 緩衝鉸鏈(blun)厚門板用 | F42: 負90度 | I42: 箱
D43: 緩衝鉸鏈(blun)厚門板用 | F43: 180度 | I43: 箱
A44: 劉軒魁 | D44: KHS絞鏈 | F44: 六分 | I44: 箱
A45: 劉軒魁 | D45: KHS絞鏈 | F45: 三分 | I45: 箱
A46: 劉軒魁 | D46: KHS絞鏈 | F46: 入柱 | I46: 箱
A47: 劉軒魁 | C47: 積甲 | D47: 木螺絲 | F47: 5 | I47: 件
...

Sheet 色號
A1: 板材色號 | B1: 色號 板名 | C1: 板材 廠商_1 | D1: 封邊色號 | E1: 欄1
A2: 9999 | B2: 發泡板
A3: 1 | B3: 白身
A4: 1434 | B4: 晨星白橡 | C4: 翰可
A5: 1614 | B5: 銀白核桃 | C5: 翰可 | D5: P276N
A6: 1633 | B6: 清新楓木 | C6: 翰可 | D6: P245B
A7: 1644 | B7: 歐洲橡木 | C7: 翰可 | D7: P279F
A8: 1703 | B8: 幻影黑橡 | C8: 翰可 | D8: P140B
A9: 1754 | B9: 南洋玉檀 | C9: 翰可
A10: 1764 | B10: 古典白橡 | C10: 翰可 | D10: P276H
A11: 1774 | B11: 淺棕橡木 | C11: 翰可
A12: 1784 | B12: 鐵刀木 | C12: 翰可 | D12: P279J
A13: 1794 | B13: 皇家胡桃 | C13: 翰可 | D13: P276E
A14: 1804 | B14: 夜影檀木 | C14: 翰可 | D14: P197Q
A15: 1814 | B15: 東方栗木 | C15: 翰可 | D15: P196G
A16: 2101 | B16: 金屬灰 | C16: 翰可 | D16: P9378
A17: 2102 | B17: 和風金 | C17: 翰可
A18: 2103 | B18: 流金棕 | C18: 翰可
A19: 2104 | B19: 香檳金 | C19: 翰可
A20: 2317 | B20: 卡拉白 | C20: 翰可
A21: 2327 | B21: 絕色松華 | C21: 翰可
A22: 2330 | B22: 雪銀狐 | C22: 翰可 | D22: P705A
A23: 2353 | B23: 月雲白 | C23: 翰可
A24: 2454 | B24: 北國雪樹 | C24: 翰可 | D24: P160F
A25: 2624 | B25: 淺白榆木 | C25: 翰可 | D25: P181G
A26: 2653 | B26: 懷舊白橡 | C26: 翰可
A27: 2664 | B27: 北美櫻桃 | C27: 翰可 | D27: P214A
A28: 2673 | B28: 黃金柚木 | C28: 翰可 | D28: M69
A29: 2684 | B29: 可可櫻桃 | C29: 翰可 | D29: JM168C
A30: 2693 | B30: 英式胡桃 | C30: 翰可 | D30: P3468C
A31: 2713 | B31: 深紋棕橡 | C31: 翰可 | D31: P181D
A32: 2724 | B32: 晨影榆木 | C32: 翰可 | D32: P276M
A33: 2733 | B33: 燻染尤加利 | C33: 翰可
A34: 2744 | B34: 桃花心木 | C34: 翰可 | D34: M69
A35: 2882 | B35: 輝夜岩 | C35: 翰可
A36: 3008 | B36: 南美胡桃 | C36: 翰可
A37: 3131 | B37: 霧色榆木 | C37: 翰可
A38: 3218 | B38: 奶油澄木 | C38: 翰可 | D38: 達思SK6679C
A39: 3293 | B39: 青森雪松 | C39: 翰可
A40: 3338 | B40: 黎明橡木 | C40: 翰可
...

Sheet 拆單用
A1: Column1 | B1: Column2 | C1: Column3 | D1: Column4 | E1: Column5 | F1: Column6 | G1: Column7 | H1: Column8 | I1: Column9 | J1: Column10 | K1: Column11 | L1: Column12
A2: 桶身 | B2: 內部 | C2: 外部 | D2: 抽屜 | E2: 抽箱 | F2: 抽盤_不見軌道 | G2: 床架_臥塌 | H2: 內部五金 | I2: 外部五金 | J2: 抽屜五金 | K2: 其它五金 | L2: 衣廚五金
A3: 頂板 | B3: 固隔 | C3: 踢腳板 | D3: 抽頭 | E3: 左側板 | F3: 抽盤 | G3: 左側板 | H3: 活隔粒 | I3: 調整腳(10-12cm) | J3: 20公分三節式滑軌 | K3: 大頭螺絲 | L3: 吊衣桿
A4: 底板 | B4: 活隔 | C4: 左門板 | D4: 左抽牆 | E4: 右側板 | F4: 抽盤抽頭 | G4: 右側板 | H4: 固隔器(金屬)含螺絲 | I4: 調整腳(8-10cm) | J4: 25公分三節式緩衝滑軌 | K4: 木螺絲 1.5cm | L4: 吊 耳
A5: 左側板 | B5: 中立板 | C5: 右門板 | D5: 右抽牆 | E5: 頂板 | F5: 左右抽盤骨料（對切） | G5: 上支桿 | I5: 平行鉸鏈(-90°) | J5: 30公分三節式緩衝滑軌 | K5: 木螺絲 3cm | L5: 吊衣桿(不鏽鋼)
A6: 右側板 | B6: 中立板(退) | C6: 指縫擋板 | D6: 前抽牆 | E6: 底板 | F6: 前後抽盤骨料（對切） | G6: 下支桿 | I6: 緩衝鉸鏈 三分 | J6: 35公分三節式緩衝滑軌 | K6: 木螺絲 4cm | L6: 吊 耳(不鏽鋼)
A7: 背板 | B7: 固隔(退) | C7: 指縫擋板(對切) | D7: 後抽牆 | E7: 上前拉桿 | G7: 踢腳骨料 | I7: KHS絞鏈(台製) 六分 | J7: 40公分三節式緩衝滑軌 | K7: 木螺絲 5cm | L7: 吊衣桿中通
A8: 背拉桿 | B8: 活固隔 | C8: 木滑門 | D8: 抽底 | E8: 下前拉桿 | G8: 入柱背板 | I8: 川湖緩衝鉸鏈 六分 | J8: 45公分三節式緩衝滑軌 | K8: 六角縲絲7cm
A9: 底板(退) | B9: 內頂板 | D9: 抽屜拉桿 | E9: 上後拉桿 | I9: 川湖緩衝鉸鏈 三分 | J9: 50公分三節式緩衝滑軌 | K9: 拉米諾
A10: 天地蓋頂板 | B10: 內左側落板 | C10: 線板 | D10: 指縫擋板 | E10: 下後拉桿 | I10: 川湖緩衝鉸鏈 入柱 | J10: 55公分三節式緩衝滑軌 | K10: 通風片(鋁合金)
A11: 天地蓋底板 | B11: 內右側落板 | C11: 層板 | D11: 入柱抽頭 | E11: 中立板 | I11: Blun緩衝鉸鏈 六分 | J11: 60公分三節式緩衝滑軌 | K11: 出線孔圓 5.5公分
A12: 天地蓋左側板 | B12: 內底板 | C12: 壁面層板 | D12: 入柱抽底 | E12: 入柱背板 | I12: Blun緩衝鉸鏈 三分 | J12: 30公分川湖緩衝軌道 | K12: 出線孔 長方形
A13: 天地蓋右側板 | B13: 內左側板 | C13: 桌板 | D13: 外蓋抽底 | I13: Blun緩衝鉸鏈 入柱 | J13: 35公分川湖緩衝軌道
A14: 天地蓋左側落板 | B14: 內右側板 | C14: 台面 | D14: 假抽頭 | I14: 寸15厚門緩衝鉸鏈 六分 | J14: 40公分川湖緩衝軌道 | K14: 油煙機
A15: 天地蓋右側落板 | B15: 上前平肢 | C15: 床板 | D15: 格子抽(直) | I15: 圓柱拍拍手 | J15: 45公分川湖緩衝軌道 | K15: 檯面爐
A16: 左側落板 | B16: 上後平肢 | C16: 假門板 | D16: 格子抽(橫) | I16: L片 鐵製 | J16: 50公分川湖緩衝軌道 | K16: 烘碗機
A17: 右側落板 | B17: 上前立肢 | C17: 上掀門板 | I17: L片 塑膠製 | J17: 30公分坐式緩衝滑軌 | K17: 水槽
A18: 入柱背板 | B18: 上後立肢 | C18: 平掀門板 | I18: 檯面輔助支撐架 | J18: 35公分坐式緩衝滑軌 | K18: 水龍頭
A19: 外蓋背板 | B19: 下前立肢 | C19: 下掀門板 | I19: 層板L架（白烤） | J19: 40公分坐式緩衝滑軌 | K19: 人造石檯面
A20: 入柱底板 | B20: 下後立肢 | C20: 拉籃門板 | I20: 層板縲絲 | J20: 45公分坐式緩衝滑軌
A21: 外蓋底板 | B21: 下前平肢 | C21: 補板 | I21: 深22mm肚臍鎖(門片用) | J21: 50公分坐式緩衝滑軌
A22: 前側板 | B22: 下後平肢 | C22: 封板 | I22: 深36mm肚臍鎖(抽頭用) | J22: 30公分彈壓式緩衝滑軌
A23: 後側板 | B23: 內補板 | C23: 上封板 | I23: 平掀桿 | J23: 35公分彈壓式緩衝滑軌
A24: 外左側板 | B24: 內補板(對切) | C24: 下封板 | I24: 上掀桿 | J24: 40公分彈壓式緩衝滑軌
A25: 外右側板 | B25: 橫撐 | C25: 前封板 | I25: 任意停 | J25: 45公分彈壓式緩衝滑軌
B26: 立板 | C26: 後封板 | I26: 崁把手 | J26: 50公分彈壓式緩衝滑軌
C27: 左封板 | I27: 上軌(A339鋁擠) | J27: 55公分彈壓式緩衝滑軌
C28: 右封板 | I28: 雙下軌(平輪77鋁擠) | J28: 15公分瓶罐側拉架(座式）
C29: 外蓋封板 | I29: 雙培林上輪 | J29: 20公分瓶罐側拉架(座式）
C30: 入柱封板 | I30: 白鐵輪 | J30: 高身櫃拉籃
C31: 上蓋板 | I31: 鋁飾條 | J31: 鋁抽(小抽84)
C32: 直立板 | I32: 毛刷條（短） | J32: 鋁抽(薄高抽116)
C33: 補角料 | I33: 毛刷條（長） | J33: 鋁抽(薄高高抽167)
C34: 燈擋板 | I34: 上軌(ㄇ型)
C35: 燈擋板(對切) | I35: 下軌(V型)
C36: 鋁框滑門 | I36: 上輪(塑膠)
I37: 下V輪(塑膠)
C38: 上軌道板
C39: 下軌道板
C40: 左軌道板
...

Sheet 標記
A1: Column1 | B1: Column2 | C1: Column3 | D1: Column4 | G1: 設計師
A2: 背板溝 | B2: A | C2: 4 | G2: 吳心彤
A3: 側 | B3: AA | C3: 8 | G3: 溫培堯
A4: 面 | B4: AP | C4: 12 | G4: 張修睿
A5: 排 | C5: 17 | G5: 郭博豪
A6: 二排 | B6: PP | C6: 18 | G6: 呂映澄
A7: 打型 | B7: P | C7: 20 | G7: 陳昭宇
A8: 固 | B8: A | C8: 23
A9: 鉸2 | C9: 25 | G9: JEFF 宋綻威
A10: 鉸3 | C10: 30
A11: 鉸4 | C11: 34
A12: 上斜 | C12: 40
A13: 下斜 | C13: 51
A14: 側斜 | C14: 50
A15: 崁 | C15: 1
A16: Z
A17: 輪
A18: 軌道
A19: 退20
A20: 燈溝

Sheet 料單
C1: =_xlfn.IFNA(CONCATENATE(TEXT(K2,"yyyymmdd"),G1),"") -> 2026101401 | F1: 流水號： | G1: 01
A2: 案場： | J2: 訂貨日期： | K2: =TODAY() -> 46309 | N2: 1修改日期：
A3: 業務/設計師： | J3: 交貨日期： | L3: 拉、KD | N3: 2修改日期：
A4: 板材總片數： | C4: =L8+L46+L85+L124+L163+L202+L241+L280+L319+L358+L397+L436+L475+L514+L553+L592+L631+L670+L709+L748+L787+L826+L865+L904+L943+L982+L1021+L1060+L1099+L1138+L1177+L1216+L1255+L1294+L1333+L1372+L1411+L1450+L1489+L1528+L1567+L1606+L1645+L1684+L1723+L1762+L1801+L1840+L1879+L1918 -> 0 | J4: 送貨地址： | N4: 3修改日期：
A5: 板材總才數： | B5: =ROUND(SUM(板材才數分析.!P:P),0) -> 0
A7: 櫃體名稱 | D7: {=_xlfn.IFS(OR(C7="水槽櫃",C7="爐台櫃"),"無頂板",C7="油機吊櫃","無底板",TRUE,0)} -> 0
A8: 櫃號 | C8: 1 | K8: 板材片數： | L8: =SUMIF(D14:D43,"<>*五金",K14:K43) -> 0
A9: 櫃高 | K9: 板材才數： | L9: =板材才數分析.!P31 -> 0 | T9: =IF(AND(OR($E14="右側板",$E14="左側板"),COUNTIF($E$14:$E$43,"活隔")>0),"排孔","")
A10: 櫃深 | D10: 不含門 | K10: 批次： | L10: 1
A11: 櫃寬
A12: 櫃名 | C12: 專案 | D12: 類別 | E12: 板材名稱 | F12: 開板尺寸 | K12: 生產 數量 | L12: 板材 色號 | M12: 色號 名稱 | N12: 板商 | O12: 封邊 色號 | P12: 備註 | Q12: 備註 | R12: 備註 | S12: 備註 | T12: 提醒 | U12: 批次
F13: 長(同紋) | G13: 封邊 | H13: 寬 | I13: 封邊 | J13: 厚
A14: =$C$7 -> 0 | C14: =(C8*1000)+1 -> 1001 | D14: 桶身 | E14: 頂板 | F14: =C11-35 -> -35 | G14: =IF( OR( $E14="頂板",$E14="底板",$E14="右側板",$E14="左側板", $E14="天地蓋頂板",$E14="天地蓋底板",$E14="天地蓋右側板",$E14="天地蓋左側板", $E14="前抽牆",$E14="後抽牆",$E14="左抽牆",$E14="右抽牆", $E14="踢腳板",$E14="補板",$E14="固隔",$E14="活隔", $E14="中立板",$E14="中立板(退)",$E14="固隔(退)",$E14="活固隔",$E14="立板", $E14="內頂板",$E14="內左側落板",$E14="內右側落板",$E14="內底板", $E14="內左側板",$E14="內右側板", $E14="上前平肢",$E14="上後平肢",$E14="上前立肢",$E14="上後立肢", $E14="下前立肢",$E14="下後立肢",$E14="下前平肢",$E14="下後平肢", $E14="左側落板",$E14="右側落板", $E14="外蓋背板",$E14="台面",$E14="床板",$E14="假門板", $E14="上掀門板",$E14="平掀門板",$E14="下掀門板", $E14="左門板",$E14="右門板", $E14="抽盤",$E14="抽盤抽頭", $E14="上軌道板",$E14="下軌道板",$E14="左軌道板",$E14="右軌道板",$E14="指縫擋板",$E14="左木框滑門",$E14="右木框滑門", $E14="層板",$E14="壁面層板",$E14="桌板",$E14="上封板",$E14="下封板",$E14="左封板",$E14="右封板", $E14="左圓角側板",$E14="右圓角側板",$E14="抽頭",$E14="入柱抽頭",$E14="假抽頭",$E14="背拉桿",$E14="木滑門",$E14="抽屜拉桿" ), "AA", "" ) -> AA | H14: =C10 -> 0 | I14: =IF( OR( $E14="右側板",$E14="左側板",$E14="活隔", $E14="天地蓋頂板",$E14="天地蓋底板", $E14="左門板",$E14="右門板", $E14="左側落板",$E14="右側落板", $E14="外蓋背板",$E14="活固隔", $E14="左木框滑門",$E14="右木框滑門", $E14="左鋁框滑門",$E14="右鋁框滑門", $E14="桌板",$E14="台面",$E14="床板",$E14="假門板", $E14="上掀門板",$E14="平掀門板",$E14="下掀門板", $E14="抽盤抽頭",$E14="抽盤",$E14="層板",$E14="壁面層板", $E14="上封板",$E14="下封板",$E14="左封板",$E14="右封板", $E14="抽頭",$E14="踢腳板",$E14="補板",$E14="木滑門" ), "AA", "" ) | J14: 18 | M14: =IFERROR(VLOOKUP(L14,色號!A:B,2,FALSE),"") | N14: =IFERROR(VLOOKUP(M14,色號!B:C,2,FALSE),"") | O14: =IFERROR(VLOOKUP(L14,色號!A:D,4,FALSE),"") | P14: =IF( OR($E14="左門板", $E14="右門板"), "鉸" & IF($F14<=1000, 2, IF($F14<=1800, 3, 4)), IF( $E14="入柱背板", "側", IF( $E14="外蓋背板", "面", IF( AND(COUNTIF($E$14:$E$43,"入柱背板")>0, OR($E14="頂板", $E14="底板")), "面", IF( AND(COUNTIF($E$14:$E$43,"外蓋背板")>0, OR($E14="左側板", $E14="右側板")), "側", IF( AND( COUNTIF($E$14:$E$43,"入柱背板")=0, COUNTIF($E$14:$E$43,"外蓋背板")=0, OR( AND(COUNTIF($E$14:$E$43,"背板")>0, OR($E14="左側板",$E14="右側板",$E14="頂板",$E14="底板",$E14="天地蓋右側板",$E14="天地蓋左側板",$E14="天地蓋底板",$E14="天地蓋頂板")), AND(COUNTIF($E$14:$E$43,"抽底")>0, OR($E14="右抽牆",$E14="左抽牆",$E14="前抽牆",$E14="後抽牆")) ) ), "背板溝", "" ) ) ) ) ) ) -> 背板溝 | Q14: =IF(OR($E14="天地蓋右側板",$E14="天地蓋左側板"), "側 面", IF(OR($E14="背拉桿",$E14="中立板",$E14="頂板",$E14="底板",$E14="前抽牆",$E14="後抽牆",$E14="內左側落板",$E14="內右側落板",$E14="抽屜拉桿",$E14="立板"), "側", IF(OR($E14="木滑門",$E14="鋁框滑門"), "輪", IF(OR($E14="右側板",$E14="左側板",$E14="右抽牆",$E14="左抽牆",$E14="天地蓋頂板",$E14="天地蓋底板",$E14="內頂板"), "面", IF($E14="固隔","固","") ) ) ) ) -> 側 | R14: =IF( OR($E14="左側板",$E14="右側板",$E14="天地蓋左側板",$E14="天地蓋右側板",$E14="中立板",$E14="立板"), "排","") | T14: =IF($E14="中立板","面開槽？排孔？", IF($E14="木框滑門","前排孔要退喔！", IF(OR($E14="左門板",$E14="右門板",$E14="抽頭"),"把手？", IF(OR($E14="左側板",$E14="右側板",$E14="天地蓋右側板",$E14="天地蓋左側板"),"排孔？","")))) | U14: =IF(E14="","",$L$10) -> 1
A15: =$C$7 -> 0 | C15: =C14+1 -> 1002 | D15: 桶身 | E15: 底板 | F15: =C11-35 -> -35 | G15: =IF( OR( $E15="頂板",$E15="底板",$E15="右側板",$E15="左側板", $E15="天地蓋頂板",$E15="天地蓋底板",$E15="天地蓋右側板",$E15="天地蓋左側板", $E15="前抽牆",$E15="後抽牆",$E15="左抽牆",$E15="右抽牆", $E15="踢腳板",$E15="補板",$E15="固隔",$E15="活隔", $E15="中立板",$E15="中立板(退)",$E15="固隔(退)",$E15="活固隔",$E15="立板", $E15="內頂板",$E15="內左側落板",$E15="內右側落板",$E15="內底板", $E15="內左側板",$E15="內右側板", $E15="上前平肢",$E15="上後平肢",$E15="上前立肢",$E15="上後立肢", $E15="下前立肢",$E15="下後立肢",$E15="下前平肢",$E15="下後平肢", $E15="左側落板",$E15="右側落板", $E15="外蓋背板",$E15="台面",$E15="床板",$E15="假門板", $E15="上掀門板",$E15="平掀門板",$E15="下掀門板", $E15="左門板",$E15="右門板", $E15="抽盤",$E15="抽盤抽頭", $E15="上軌道板",$E15="下軌道板",$E15="左軌道板",$E15="右軌道板",$E15="指縫擋板",$E15="左木框滑門",$E15="右木框滑門", $E15="層板",$E15="壁面層板",$E15="桌板",$E15="上封板",$E15="下封板",$E15="左封板",$E15="右封板", $E15="左圓角側板",$E15="右圓角側板",$E15="抽頭",$E15="入柱抽頭",$E15="假抽頭",$E15="背拉桿",$E15="木滑門",$E15="抽屜拉桿" ), "AA", "" ) -> AA | H15: =C10 -> 0 | I15: =IF( OR( $E15="右側板",$E15="左側板",$E15="活隔", $E15="天地蓋頂板",$E15="天地蓋底板", $E15="左門板",$E15="右門板", $E15="左側落板",$E15="右側落板", $E15="外蓋背板",$E15="活固隔", $E15="左木框滑門",$E15="右木框滑門", $E15="左鋁框滑門",$E15="右鋁框滑門", $E15="桌板",$E15="台面",$E15="床板",$E15="假門板", $E15="上掀門板",$E15="平掀門板",$E15="下掀門板", $E15="抽盤抽頭",$E15="抽盤",$E15="層板",$E15="壁面層板", $E15="上封板",$E15="下封板",$E15="左封板",$E15="右封板", $E15="抽頭",$E15="踢腳板",$E15="補板",$E15="木滑門" ), "AA", "" ) | J15: 18 | M15: =IFERROR(VLOOKUP(L15,色號!A:B,2,FALSE),"") | N15: =IFERROR(VLOOKUP(M15,色號!B:C,2,FALSE),"") | O15: =IFERROR(VLOOKUP(L15,色號!A:D,4,FALSE),"") | P15: =IF( OR($E15="左門板", $E15="右門板"), "鉸" & IF($F15<=1000, 2, IF($F15<=1800, 3, 4)), IF( $E15="入柱背板", "側", IF( $E15="外蓋背板", "面", IF( AND(COUNTIF($E$14:$E$43,"入柱背板")>0, OR($E15="頂板", $E15="底板")), "面", IF( AND(COUNTIF($E$14:$E$43,"外蓋背板")>0, OR($E15="左側板", $E15="右側板")), "側", IF( AND( COUNTIF($E$14:$E$43,"入柱背板")=0, COUNTIF($E$14:$E$43,"外蓋背板")=0, OR( AND(COUNTIF($E$14:$E$43,"背板")>0, OR($E15="左側板",$E15="右側板",$E15="頂板",$E15="底板",$E15="天地蓋右側板",$E15="天地蓋左側板",$E15="天地蓋底板",$E15="天地蓋頂板")), AND(COUNTIF($E$14:$E$43,"抽底")>0, OR($E15="右抽牆",$E15="左抽牆",$E15="前抽牆",$E15="後抽牆")) ) ), "背板溝", "" ) ) ) ) ) ) -> 背板溝 | Q15: =IF(OR($E15="天地蓋右側板",$E15="天地蓋左側板"), "側 面", IF(OR($E15="背拉桿",$E15="中立板",$E15="頂板",$E15="底板",$E15="前抽牆",$E15="後抽牆",$E15="內左側落板",$E15="內右側落板",$E15="抽屜拉桿",$E15="立板"), "側", IF(OR($E15="木滑門",$E15="鋁框滑門"), "輪", IF(OR($E15="右側板",$E15="左側板",$E15="右抽牆",$E15="左抽牆",$E15="天地蓋頂板",$E15="天地蓋底板",$E15="內頂板"), "面", IF($E15="固隔","固","") ) ) ) ) -> 側 | R15: =IF( OR($E15="左側板",$E15="右側板",$E15="天地蓋左側板",$E15="天地蓋右側板",$E15="中立板",$E15="立板"), "排","") | T15: =IF($E15="中立板","面開槽？排孔？", IF($E15="木框滑門","前排孔要退喔！", IF(OR($E15="左門板",$E15="右門板",$E15="抽頭"),"把手？", IF(OR($E15="左側板",$E15="右側板",$E15="天地蓋右側板",$E15="天地蓋左側板"),"排孔？","")))) | U15: =IF(E15="","",$L$10) -> 1
A16: =$C$7 -> 0 | C16: =C15+1 -> 1003 | D16: 桶身 | E16: 左側板 | F16: =C9 -> 0 | G16: =IF( OR( $E16="頂板",$E16="底板",$E16="右側板",$E16="左側板", $E16="天地蓋頂板",$E16="天地蓋底板",$E16="天地蓋右側板",$E16="天地蓋左側板", $E16="前抽牆",$E16="後抽牆",$E16="左抽牆",$E16="右抽牆", $E16="踢腳板",$E16="補板",$E16="固隔",$E16="活隔", $E16="中立板",$E16="中立板(退)",$E16="固隔(退)",$E16="活固隔",$E16="立板", $E16="內頂板",$E16="內左側落板",$E16="內右側落板",$E16="內底板", $E16="內左側板",$E16="內右側板", $E16="上前平肢",$E16="上後平肢",$E16="上前立肢",$E16="上後立肢", $E16="下前立肢",$E16="下後立肢",$E16="下前平肢",$E16="下後平肢", $E16="左側落板",$E16="右側落板", $E16="外蓋背板",$E16="台面",$E16="床板",$E16="假門板", $E16="上掀門板",$E16="平掀門板",$E16="下掀門板", $E16="左門板",$E16="右門板", $E16="抽盤",$E16="抽盤抽頭", $E16="上軌道板",$E16="下軌道板",$E16="左軌道板",$E16="右軌道板",$E16="指縫擋板",$E16="左木框滑門",$E16="右木框滑門", $E16="層板",$E16="壁面層板",$E16="桌板",$E16="上封板",$E16="下封板",$E16="左封板",$E16="右封板", $E16="左圓角側板",$E16="右圓角側板",$E16="抽頭",$E16="入柱抽頭",$E16="假抽頭",$E16="背拉桿",$E16="木滑門",$E16="抽屜拉桿" ), "AA", "" ) -> AA | H16: =C10 -> 0 | I16: =IF( OR( $E16="右側板",$E16="左側板",$E16="活隔", $E16="天地蓋頂板",$E16="天地蓋底板", $E16="左門板",$E16="右門板", $E16="左側落板",$E16="右側落板", $E16="外蓋背板",$E16="活固隔", $E16="左木框滑門",$E16="右木框滑門", $E16="左鋁框滑門",$E16="右鋁框滑門", $E16="桌板",$E16="台面",$E16="床板",$E16="假門板", $E16="上掀門板",$E16="平掀門板",$E16="下掀門板", $E16="抽盤抽頭",$E16="抽盤",$E16="層板",$E16="壁面層板", $E16="上封板",$E16="下封板",$E16="左封板",$E16="右封板", $E16="抽頭",$E16="踢腳板",$E16="補板",$E16="木滑門" ), "AA", "" ) -> AA | J16: 18 | M16: =IFERROR(VLOOKUP(L16,色號!A:B,2,FALSE),"") | N16: =IFERROR(VLOOKUP(M16,色號!B:C,2,FALSE),"") | O16: =IFERROR(VLOOKUP(L16,色號!A:D,4,FALSE),"") | P16: =IF( OR($E16="左門板", $E16="右門板"), "鉸" & IF($F16<=1000, 2, IF($F16<=1800, 3, 4)), IF( $E16="入柱背板", "側", IF( $E16="外蓋背板", "面", IF( AND(COUNTIF($E$14:$E$43,"入柱背板")>0, OR($E16="頂板", $E16="底板")), "面", IF( AND(COUNTIF($E$14:$E$43,"外蓋背板")>0, OR($E16="左側板", $E16="右側板")), "側", IF( AND( COUNTIF($E$14:$E$43,"入柱背板")=0, COUNTIF($E$14:$E$43,"外蓋背板")=0, OR( AND(COUNTIF($E$14:$E$43,"背板")>0, OR($E16="左側板",$E16="右側板",$E16="頂板",$E16="底板",$E16="天地蓋右側板",$E16="天地蓋左側板",$E16="天地蓋底板",$E16="天地蓋頂板")), AND(COUNTIF($E$14:$E$43,"抽底")>0, OR($E16="右抽牆",$E16="左抽牆",$E16="前抽牆",$E16="後抽牆")) ) ), "背板溝", "" ) ) ) ) ) ) -> 背板溝 | Q16: =IF(OR($E16="天地蓋右側板",$E16="天地蓋左側板"), "側 面", IF(OR($E16="背拉桿",$E16="中立板",$E16="頂板",$E16="底板",$E16="前抽牆",$E16="後抽牆",$E16="內左側落板",$E16="內右側落板",$E16="抽屜拉桿",$E16="立板"), "側", IF(OR($E16="木滑門",$E16="鋁框滑門"), "輪", IF(OR($E16="右側板",$E16="左側板",$E16="右抽牆",$E16="左抽牆",$E16="天地蓋頂板",$E16="天地蓋底板",$E16="內頂板"), "面", IF($E16="固隔","固","") ) ) ) ) -> 面 | R16: =IF( OR($E16="左側板",$E16="右側板",$E16="天地蓋左側板",$E16="天地蓋右側板",$E16="中立板",$E16="立板"), "排","") -> 排 | T16: =IF($E16="中立板","面開槽？排孔？", IF($E16="木框滑門","前排孔要退喔！", IF(OR($E16="左門板",$E16="右門板",$E16="抽頭"),"把手？", IF(OR($E16="左側板",$E16="右側板",$E16="天地蓋右側板",$E16="天地蓋左側板"),"排孔？","")))) -> 排孔？ | U16: =IF(E16="","",$L$10) -> 1
A17: =$C$7 -> 0 | C17: =C16+1 -> 1004 | D17: 桶身 | E17: 右側板 | F17: =C9 -> 0 | G17: =IF( OR( $E17="頂板",$E17="底板",$E17="右側板",$E17="左側板", $E17="天地蓋頂板",$E17="天地蓋底板",$E17="天地蓋右側板",$E17="天地蓋左側板", $E17="前抽牆",$E17="後抽牆",$E17="左抽牆",$E17="右抽牆", $E17="踢腳板",$E17="補板",$E17="固隔",$E17="活隔", $E17="中立板",$E17="中立板(退)",$E17="固隔(退)",$E17="活固隔",$E17="立板", $E17="內頂板",$E17="內左側落板",$E17="內右側落板",$E17="內底板", $E17="內左側板",$E17="內右側板", $E17="上前平肢",$E17="上後平肢",$E17="上前立肢",$E17="上後立肢", $E17="下前立肢",$E17="下後立肢",$E17="下前平肢",$E17="下後平肢", $E17="左側落板",$E17="右側落板", $E17="外蓋背板",$E17="台面",$E17="床板",$E17="假門板", $E17="上掀門板",$E17="平掀門板",$E17="下掀門板", $E17="左門板",$E17="右門板", $E17="抽盤",$E17="抽盤抽頭", $E17="上軌道板",$E17="下軌道板",$E17="左軌道板",$E17="右軌道板",$E17="指縫擋板",$E17="左木框滑門",$E17="右木框滑門", $E17="層板",$E17="壁面層板",$E17="桌板",$E17="上封板",$E17="下封板",$E17="左封板",$E17="右封板", $E17="左圓角側板",$E17="右圓角側板",$E17="抽頭",$E17="入柱抽頭",$E17="假抽頭",$E17="背拉桿",$E17="木滑門",$E17="抽屜拉桿" ), "AA", "" ) -> AA | H17: =C10 -> 0 | I17: =IF( OR( $E17="右側板",$E17="左側板",$E17="活隔", $E17="天地蓋頂板",$E17="天地蓋底板", $E17="左門板",$E17="右門板", $E17="左側落板",$E17="右側落板", $E17="外蓋背板",$E17="活固隔", $E17="左木框滑門",$E17="右木框滑門", $E17="左鋁框滑門",$E17="右鋁框滑門", $E17="桌板",$E17="台面",$E17="床板",$E17="假門板", $E17="上掀門板",$E17="平掀門板",$E17="下掀門板", $E17="抽盤抽頭",$E17="抽盤",$E17="層板",$E17="壁面層板", $E17="上封板",$E17="下封板",$E17="左封板",$E17="右封板", $E17="抽頭",$E17="踢腳板",$E17="補板",$E17="木滑門" ), "AA", "" ) -> AA | J17: 18 | M17: =IFERROR(VLOOKUP(L17,色號!A:B,2,FALSE),"") | N17: =IFERROR(VLOOKUP(M17,色號!B:C,2,FALSE),"") | O17: =IFERROR(VLOOKUP(L17,色號!A:D,4,FALSE),"") | P17: =IF( OR($E17="左門板", $E17="右門板"), "鉸" & IF($F17<=1000, 2, IF($F17<=1800, 3, 4)), IF( $E17="入柱背板", "側", IF( $E17="外蓋背板", "面", IF( AND(COUNTIF($E$14:$E$43,"入柱背板")>0, OR($E17="頂板", $E17="底板")), "面", IF( AND(COUNTIF($E$14:$E$43,"外蓋背板")>0, OR($E17="左側板", $E17="右側板")), "側", IF( AND( COUNTIF($E$14:$E$43,"入柱背板")=0, COUNTIF($E$14:$E$43,"外蓋背板")=0, OR( AND(COUNTIF($E$14:$E$43,"背板")>0, OR($E17="左側板",$E17="右側板",$E17="頂板",$E17="底板",$E17="天地蓋右側板",$E17="天地蓋左側板",$E17="天地蓋底板",$E17="天地蓋頂板")), AND(COUNTIF($E$14:$E$43,"抽底")>0, OR($E17="右抽牆",$E17="左抽牆",$E17="前抽牆",$E17="後抽牆")) ) ), "背板溝", "" ) ) ) ) ) ) -> 背板溝 | Q17: =IF(OR($E17="天地蓋右側板",$E17="天地蓋左側板"), "側 面", IF(OR($E17="背拉桿",$E17="中立板",$E17="頂板",$E17="底板",$E17="前抽牆",$E17="後抽牆",$E17="內左側落板",$E17="內右側落板",$E17="抽屜拉桿",$E17="立板"), "側", IF(OR($E17="木滑門",$E17="鋁框滑門"), "輪", IF(OR($E17="右側板",$E17="左側板",$E17="右抽牆",$E17="左抽牆",$E17="天地蓋頂板",$E17="天地蓋底板",$E17="內頂板"), "面", IF($E17="固隔","固","") ) ) ) ) -> 面 | R17: =IF( OR($E17="左側板",$E17="右側板",$E17="天地蓋左側板",$E17="天地蓋右側板",$E17="中立板",$E17="立板"), "排","") -> 排 | T17: =IF($E17="中立板","面開槽？排孔？", IF($E17="木框滑門","前排孔要退喔！", IF(OR($E17="左門板",$E17="右門板",$E17="抽頭"),"把手？", IF(OR($E17="左側板",$E17="右側板",$E17="天地蓋右側板",$E17="天地蓋左側板"),"排孔？","")))) -> 排孔？ | U17: =IF(E17="","",$L$10) -> 1
A18: =$C$7 -> 0 | C18: =C17+1 -> 1005 | D18: 桶身 | E18: 背板 | F18: =C9-22 -> -22 | G18: =IF( OR( $E18="頂板",$E18="底板",$E18="右側板",$E18="左側板", $E18="天地蓋頂板",$E18="天地蓋底板",$E18="天地蓋右側板",$E18="天地蓋左側板", $E18="前抽牆",$E18="後抽牆",$E18="左抽牆",$E18="右抽牆", $E18="踢腳板",$E18="補板",$E18="固隔",$E18="活隔", $E18="中立板",$E18="中立板(退)",$E18="固隔(退)",$E18="活固隔",$E18="立板", $E18="內頂板",$E18="內左側落板",$E18="內右側落板",$E18="內底板", $E18="內左側板",$E18="內右側板", $E18="上前平肢",$E18="上後平肢",$E18="上前立肢",$E18="上後立肢", $E18="下前立肢",$E18="下後立肢",$E18="下前平肢",$E18="下後平肢", $E18="左側落板",$E18="右側落板", $E18="外蓋背板",$E18="台面",$E18="床板",$E18="假門板", $E18="上掀門板",$E18="平掀門板",$E18="下掀門板", $E18="左門板",$E18="右門板", $E18="抽盤",$E18="抽盤抽頭", $E18="上軌道板",$E18="下軌道板",$E18="左軌道板",$E18="右軌道板",$E18="指縫擋板",$E18="左木框滑門",$E18="右木框滑門", $E18="層板",$E18="壁面層板",$E18="桌板",$E18="上封板",$E18="下封板",$E18="左封板",$E18="右封板", $E18="左圓角側板",$E18="右圓角側板",$E18="抽頭",$E18="入柱抽頭",$E18="假抽頭",$E18="背拉桿",$E18="木滑門",$E18="抽屜拉桿" ), "AA", "" ) | H18: =C11-22 -> -22 | I18: =IF( OR( $E18="右側板",$E18="左側板",$E18="活隔", $E18="天地蓋頂板",$E18="天地蓋底板", $E18="左門板",$E18="右門板", $E18="左側落板",$E18="右側落板", $E18="外蓋背板",$E18="活固隔", $E18="左木框滑門",$E18="右木框滑門", $E18="左鋁框滑門",$E18="右鋁框滑門", $E18="桌板",$E18="台面",$E18="床板",$E18="假門板", $E18="上掀門板",$E18="平掀門板",$E18="下掀門板", $E18="抽盤抽頭",$E18="抽盤",$E18="層板",$E18="壁面層板", $E18="上封板",$E18="下封板",$E18="左封板",$E18="右封板", $E18="抽頭",$E18="踢腳板",$E18="補板",$E18="木滑門" ), "AA", "" ) | J18: 4 | M18: =IFERROR(VLOOKUP(L18,色號!A:B,2,FALSE),"") | N18: =IFERROR(VLOOKUP(M18,色號!B:C,2,FALSE),"") | O18: =IFERROR(VLOOKUP(L18,色號!A:D,4,FALSE),"") | P18: =IF( OR($E18="左門板", $E18="右門板"), "鉸" & IF($F18<=1000, 2, IF($F18<=1800, 3, 4)), IF( $E18="入柱背板", "側", IF( $E18="外蓋背板", "面", IF( AND(COUNTIF($E$14:$E$43,"入柱背板")>0, OR($E18="頂板", $E18="底板")), "面", IF( AND(COUNTIF($E$14:$E$43,"外蓋背板")>0, OR($E18="左側板", $E18="右側板")), "側", IF( AND( COUNTIF($E$14:$E$43,"入柱背板")=0, COUNTIF($E$14:$E$43,"外蓋背板")=0, OR( AND(COUNTIF($E$14:$E$43,"背板")>0, OR($E18="左側板",$E18="右側板",$E18="頂板",$E18="底板",$E18="天地蓋右側板",$E18="天地蓋左側板",$E18="天地蓋底板",$E18="天地蓋頂板")), AND(COUNTIF($E$14:$E$43,"抽底")>0, OR($E18="右抽牆",$E18="左抽牆",$E18="前抽牆",$E18="後抽牆")) ) ), "背板溝", "" ) ) ) ) ) ) | Q18: =IF(OR($E18="天地蓋右側板",$E18="天地蓋左側板"), "側 面", IF(OR($E18="背拉桿",$E18="中立板",$E18="頂板",$E18="底板",$E18="前抽牆",$E18="後抽牆",$E18="內左側落板",$E18="內右側落板",$E18="抽屜拉桿",$E18="立板"), "側", IF(OR($E18="木滑門",$E18="鋁框滑門"), "輪", IF(OR($E18="右側板",$E18="左側板",$E18="右抽牆",$E18="左抽牆",$E18="天地蓋頂板",$E18="天地蓋底板",$E18="內頂板"), "面", IF($E18="固隔","固","") ) ) ) ) | R18: =IF( OR($E18="左側板",$E18="右側板",$E18="天地蓋左側板",$E18="天地蓋右側板",$E18="中立板",$E18="立板"), "排","") | T18: =IF($E18="中立板","面開槽？排孔？", IF($E18="木框滑門","前排孔要退喔！", IF(OR($E18="左門板",$E18="右門板",$E18="抽頭"),"把手？", IF(OR($E18="左側板",$E18="右側板",$E18="天地蓋右側板",$E18="天地蓋左側板"),"排孔？","")))) | U18: =IF(E18="","",$L$10) -> 1
A19: =$C$7 -> 0 | C19: =C18+1 -> 1006 | D19: 桶身 | E19: 背拉桿 | F19: =F14 -> -35 | G19: =IF( OR( $E19="頂板",$E19="底板",$E19="右側板",$E19="左側板", $E19="天地蓋頂板",$E19="天地蓋底板",$E19="天地蓋右側板",$E19="天地蓋左側板", $E19="前抽牆",$E19="後抽牆",$E19="左抽牆",$E19="右抽牆", $E19="踢腳板",$E19="補板",$E19="固隔",$E19="活隔", $E19="中立板",$E19="中立板(退)",$E19="固隔(退)",$E19="活固隔",$E19="立板", $E19="內頂板",$E19="內左側落板",$E19="內右側落板",$E19="內底板", $E19="內左側板",$E19="內右側板", $E19="上前平肢",$E19="上後平肢",$E19="上前立肢",$E19="上後立肢", $E19="下前立肢",$E19="下後立肢",$E19="下前平肢",$E19="下後平肢", $E19="左側落板",$E19="右側落板", $E19="外蓋背板",$E19="台面",$E19="床板",$E19="假門板", $E19="上掀門板",$E19="平掀門板",$E19="下掀門板", $E19="左門板",$E19="右門板", $E19="抽盤",$E19="抽盤抽頭", $E19="上軌道板",$E19="下軌道板",$E19="左軌道板",$E19="右軌道板",$E19="指縫擋板",$E19="左木框滑門",$E19="右木框滑門", $E19="層板",$E19="壁面層板",$E19="桌板",$E19="上封板",$E19="下封板",$E19="左封板",$E19="右封板", $E19="左圓角側板",$E19="右圓角側板",$E19="抽頭",$E19="入柱抽頭",$E19="假抽頭",$E19="背拉桿",$E19="木滑門",$E19="抽屜拉桿" ), "AA", "" ) -> AA | H19: 120 | I19: =IF( OR( $E19="右側板",$E19="左側板",$E19="活隔", $E19="天地蓋頂板",$E19="天地蓋底板", $E19="左門板",$E19="右門板", $E19="左側落板",$E19="右側落板", $E19="外蓋背板",$E19="活固隔", $E19="左木框滑門",$E19="右木框滑門", $E19="左鋁框滑門",$E19="右鋁框滑門", $E19="桌板",$E19="台面",$E19="床板",$E19="假門板", $E19="上掀門板",$E19="平掀門板",$E19="下掀門板", $E19="抽盤抽頭",$E19="抽盤",$E19="層板",$E19="壁面層板", $E19="上封板",$E19="下封板",$E19="左封板",$E19="右封板", $E19="抽頭",$E19="踢腳板",$E19="補板",$E19="木滑門" ), "AA", "" ) | J19: 18 | M19: =IFERROR(VLOOKUP(L19,色號!A:B,2,FALSE),"") | N19: =IFERROR(VLOOKUP(M19,色號!B:C,2,FALSE),"") | O19: =IFERROR(VLOOKUP(L19,色號!A:D,4,FALSE),"") | P19: =IF( OR($E19="左門板", $E19="右門板"), "鉸" & IF($F19<=1000, 2, IF($F19<=1800, 3, 4)), IF( $E19="入柱背板", "側", IF( $E19="外蓋背板", "面", IF( AND(COUNTIF($E$14:$E$43,"入柱背板")>0, OR($E19="頂板", $E19="底板")), "面", IF( AND(COUNTIF($E$14:$E$43,"外蓋背板")>0, OR($E19="左側板", $E19="右側板")), "側", IF( AND( COUNTIF($E$14:$E$43,"入柱背板")=0, COUNTIF($E$14:$E$43,"外蓋背板")=0, OR( AND(COUNTIF($E$14:$E$43,"背板")>0, OR($E19="左側板",$E19="右側板",$E19="頂板",$E19="底板",$E19="天地蓋右側板",$E19="天地蓋左側板",$E19="天地蓋底板",$E19="天地蓋頂板")), AND(COUNTIF($E$14:$E$43,"抽底")>0, OR($E19="右抽牆",$E19="左抽牆",$E19="前抽牆",$E19="後抽牆")) ) ), "背板溝", "" ) ) ) ) ) ) | Q19: =IF(OR($E19="天地蓋右側板",$E19="天地蓋左側板"), "側 面", IF(OR($E19="背拉桿",$E19="中立板",$E19="頂板",$E19="底板",$E19="前抽牆",$E19="後抽牆",$E19="內左側落板",$E19="內右側落板",$E19="抽屜拉桿",$E19="立板"), "側", IF(OR($E19="木滑門",$E19="鋁框滑門"), "輪", IF(OR($E19="右側板",$E19="左側板",$E19="右抽牆",$E19="左抽牆",$E19="天地蓋頂板",$E19="天地蓋底板",$E19="內頂板"), "面", IF($E19="固隔","固","") ) ) ) ) -> 側 | R19: =IF( OR($E19="左側板",$E19="右側板",$E19="天地蓋左側板",$E19="天地蓋右側板",$E19="中立板",$E19="立板"), "排","") | T19: =IF($E19="中立板","面開槽？排孔？", IF($E19="木框滑門","前排孔要退喔！", IF(OR($E19="左門板",$E19="右門板",$E19="抽頭"),"把手？", IF(OR($E19="左側板",$E19="右側板",$E19="天地蓋右側板",$E19="天地蓋左側板"),"排孔？","")))) | U19: =IF(E19="","",$L$10) -> 1
A20: =$C$7 -> 0 | C20: =C19+1 -> 1007 | D20: 內部 | E20: 中立板 | F20: =F14 -> -35 | G20: =IF( OR( $E20="頂板",$E20="底板",$E20="右側板",$E20="左側板", $E20="天地蓋頂板",$E20="天地蓋底板",$E20="天地蓋右側板",$E20="天地蓋左側板", $E20="前抽牆",$E20="後抽牆",$E20="左抽牆",$E20="右抽牆", $E20="踢腳板",$E20="補板",$E20="固隔",$E20="活隔", $E20="中立板",$E20="中立板(退)",$E20="固隔(退)",$E20="活固隔",$E20="立板", $E20="內頂板",$E20="內左側落板",$E20="內右側落板",$E20="內底板", $E20="內左側板",$E20="內右側板", $E20="上前平肢",$E20="上後平肢",$E20="上前立肢",$E20="上後立肢", $E20="下前立肢",$E20="下後立肢",$E20="下前平肢",$E20="下後平肢", $E20="左側落板",$E20="右側落板", $E20="外蓋背板",$E20="台面",$E20="床板",$E20="假門板", $E20="上掀門板",$E20="平掀門板",$E20="下掀門板", $E20="左門板",$E20="右門板", $E20="抽盤",$E20="抽盤抽頭", $E20="上軌道板",$E20="下軌道板",$E20="左軌道板",$E20="右軌道板",$E20="指縫擋板",$E20="左木框滑門",$E20="右木框滑門", $E20="層板",$E20="壁面層板",$E20="桌板",$E20="上封板",$E20="下封板",$E20="左封板",$E20="右封板", $E20="左圓角側板",$E20="右圓角側板",$E20="抽頭",$E20="入柱抽頭",$E20="假抽頭",$E20="背拉桿",$E20="木滑門",$E20="抽屜拉桿" ), "AA", "" ) -> AA | H20: =C10-22 -> -22 | I20: =IF( OR( $E20="右側板",$E20="左側板",$E20="活隔", $E20="天地蓋頂板",$E20="天地蓋底板", $E20="左門板",$E20="右門板", $E20="左側落板",$E20="右側落板", $E20="外蓋背板",$E20="活固隔", $E20="左木框滑門",$E20="右木框滑門", $E20="左鋁框滑門",$E20="右鋁框滑門", $E20="桌板",$E20="台面",$E20="床板",$E20="假門板", $E20="上掀門板",$E20="平掀門板",$E20="下掀門板", $E20="抽盤抽頭",$E20="抽盤",$E20="層板",$E20="壁面層板", $E20="上封板",$E20="下封板",$E20="左封板",$E20="右封板", $E20="抽頭",$E20="踢腳板",$E20="補板",$E20="木滑門" ), "AA", "" ) | J20: 18 | M20: =IFERROR(VLOOKUP(L20,色號!A:B,2,FALSE),"") | N20: =IFERROR(VLOOKUP(M20,色號!B:C,2,FALSE),"") | O20: =IFERROR(VLOOKUP(L20,色號!A:D,4,FALSE),"") | P20: =IF( OR($E20="左門板", $E20="右門板"), "鉸" & IF($F20<=1000, 2, IF($F20<=1800, 3, 4)), IF( $E20="入柱背板", "側", IF( $E20="外蓋背板", "面", IF( AND(COUNTIF($E$14:$E$43,"入柱背板")>0, OR($E20="頂板", $E20="底板")), "面", IF( AND(COUNTIF($E$14:$E$43,"外蓋背板")>0, OR($E20="左側板", $E20="右側板")), "側", IF( AND( COUNTIF($E$14:$E$43,"入柱背板")=0, COUNTIF($E$14:$E$43,"外蓋背板")=0, OR( AND(COUNTIF($E$14:$E$43,"背板")>0, OR($E20="左側板",$E20="右側板",$E20="頂板",$E20="底板",$E20="天地蓋右側板",$E20="天地蓋左側板",$E20="天地蓋底板",$E20="天地蓋頂板")), AND(COUNTIF($E$14:$E$43,"抽底")>0, OR($E20="右抽牆",$E20="左抽牆",$E20="前抽牆",$E20="後抽牆")) ) ), "背板溝", "" ) ) ) ) ) ) | Q20: =IF(OR($E20="天地蓋右側板",$E20="天地蓋左側板"), "側 面", IF(OR($E20="背拉桿",$E20="中立板",$E20="頂板",$E20="底板",$E20="前抽牆",$E20="後抽牆",$E20="內左側落板",$E20="內右側落板",$E20="抽屜拉桿",$E20="立板"), "側", IF(OR($E20="木滑門",$E20="鋁框滑門"), "輪", IF(OR($E20="右側板",$E20="左側板",$E20="右抽牆",$E20="左抽牆",$E20="天地蓋頂板",$E20="天地蓋底板",$E20="內頂板"), "面", IF($E20="固隔","固","") ) ) ) ) -> 側 | R20: =IF( OR($E20="左側板",$E20="右側板",$E20="天地蓋左側板",$E20="天地蓋右側板",$E20="中立板",$E20="立板"), "排","") -> 排 | T20: =IF($E20="中立板","面開槽？排孔？", IF($E20="木框滑門","前排孔要退喔！", IF(OR($E20="左門板",$E20="右門板",$E20="抽頭"),"把手？", IF(OR($E20="左側板",$E20="右側板",$E20="天地蓋右側板",$E20="天地蓋左側板"),"排孔？","")))) -> 面開槽？排孔？ | U20: =IF(E20="","",$L$10) -> 1
A21: =$C$7 -> 0 | C21: =C20+1 -> 1008 | D21: 內部 | E21: 活隔 | G21: =IF( OR( $E21="頂板",$E21="底板",$E21="右側板",$E21="左側板", $E21="天地蓋頂板",$E21="天地蓋底板",$E21="天地蓋右側板",$E21="天地蓋左側板", $E21="前抽牆",$E21="後抽牆",$E21="左抽牆",$E21="右抽牆", $E21="踢腳板",$E21="補板",$E21="固隔",$E21="活隔", $E21="中立板",$E21="中立板(退)",$E21="固隔(退)",$E21="活固隔",$E21="立板", $E21="內頂板",$E21="內左側落板",$E21="內右側落板",$E21="內底板", $E21="內左側板",$E21="內右側板", $E21="上前平肢",$E21="上後平肢",$E21="上前立肢",$E21="上後立肢", $E21="下前立肢",$E21="下後立肢",$E21="下前平肢",$E21="下後平肢", $E21="左側落板",$E21="右側落板", $E21="外蓋背板",$E21="台面",$E21="床板",$E21="假門板", $E21="上掀門板",$E21="平掀門板",$E21="下掀門板", $E21="左門板",$E21="右門板", $E21="抽盤",$E21="抽盤抽頭", $E21="上軌道板",$E21="下軌道板",$E21="左軌道板",$E21="右軌道板",$E21="指縫擋板",$E21="左木框滑門",$E21="右木框滑門", $E21="層板",$E21="壁面層板",$E21="桌板",$E21="上封板",$E21="下封板",$E21="左封板",$E21="右封板", $E21="左圓角側板",$E21="右圓角側板",$E21="抽頭",$E21="入柱抽頭",$E21="假抽頭",$E21="背拉桿",$E21="木滑門",$E21="抽屜拉桿" ), "AA", "" ) -> AA | H21: =C10-22-10 -> -32 | I21: =IF( OR( $E21="右側板",$E21="左側板",$E21="活隔", $E21="天地蓋頂板",$E21="天地蓋底板", $E21="左門板",$E21="右門板", $E21="左側落板",$E21="右側落板", $E21="外蓋背板",$E21="活固隔", $E21="左木框滑門",$E21="右木框滑門", $E21="左鋁框滑門",$E21="右鋁框滑門", $E21="桌板",$E21="台面",$E21="床板",$E21="假門板", $E21="上掀門板",$E21="平掀門板",$E21="下掀門板", $E21="抽盤抽頭",$E21="抽盤",$E21="層板",$E21="壁面層板", $E21="上封板",$E21="下封板",$E21="左封板",$E21="右封板", $E21="抽頭",$E21="踢腳板",$E21="補板",$E21="木滑門" ), "AA", "" ) -> AA | J21: 18 | M21: =IFERROR(VLOOKUP(L21,色號!A:B,2,FALSE),"") | N21: =IFERROR(VLOOKUP(M21,色號!B:C,2,FALSE),"") | O21: =IFERROR(VLOOKUP(L21,色號!A:D,4,FALSE),"") | P21: =IF( OR($E21="左門板", $E21="右門板"), "鉸" & IF($F21<=1000, 2, IF($F21<=1800, 3, 4)), IF( $E21="入柱背板", "側", IF( $E21="外蓋背板", "面", IF( AND(COUNTIF($E$14:$E$43,"入柱背板")>0, OR($E21="頂板", $E21="底板")), "面", IF( AND(COUNTIF($E$14:$E$43,"外蓋背板")>0, OR($E21="左側板", $E21="右側板")), "側", IF( AND( COUNTIF($E$14:$E$43,"入柱背板")=0, COUNTIF($E$14:$E$43,"外蓋背板")=0, OR( AND(COUNTIF($E$14:$E$43,"背板")>0, OR($E21="左側板",$E21="右側板",$E21="頂板",$E21="底板",$E21="天地蓋右側板",$E21="天地蓋左側板",$E21="天地蓋底板",$E21="天地蓋頂板")), AND(COUNTIF($E$14:$E$43,"抽底")>0, OR($E21="右抽牆",$E21="左抽牆",$E21="前抽牆",$E21="後抽牆")) ) ), "背板溝", "" ) ) ) ) ) ) | Q21: =IF(OR($E21="天地蓋右側板",$E21="天地蓋左側板"), "側 面", IF(OR($E21="背拉桿",$E21="中立板",$E21="頂板",$E21="底板",$E21="前抽牆",$E21="後抽牆",$E21="內左側落板",$E21="內右側落板",$E21="抽屜拉桿",$E21="立板"), "側", IF(OR($E21="木滑門",$E21="鋁框滑門"), "輪", IF(OR($E21="右側板",$E21="左側板",$E21="右抽牆",$E21="左抽牆",$E21="天地蓋頂板",$E21="天地蓋底板",$E21="內頂板"), "面", IF($E21="固隔","固","") ) ) ) ) | R21: =IF( OR($E21="左側板",$E21="右側板",$E21="天地蓋左側板",$E21="天地蓋右側板",$E21="中立板",$E21="立板"), "排","") | T21: =IF($E21="中立板","面開槽？排孔？", IF($E21="木框滑門","前排孔要退喔！", IF(OR($E21="左門板",$E21="右門板",$E21="抽頭"),"把手？", IF(OR($E21="左側板",$E21="右側板",$E21="天地蓋右側板",$E21="天地蓋左側板"),"排孔？","")))) | U21: =IF(E21="","",$L$10) -> 1
A22: =$C$7 -> 0 | C22: =C21+1 -> 1009 | D22: 內部 | E22: 固隔 | G22: =IF( OR( $E22="頂板",$E22="底板",$E22="右側板",$E22="左側板", $E22="天地蓋頂板",$E22="天地蓋底板",$E22="天地蓋右側板",$E22="天地蓋左側板", $E22="前抽牆",$E22="後抽牆",$E22="左抽牆",$E22="右抽牆", $E22="踢腳板",$E22="補板",$E22="固隔",$E22="活隔", $E22="中立板",$E22="中立板(退)",$E22="固隔(退)",$E22="活固隔",$E22="立板", $E22="內頂板",$E22="內左側落板",$E22="內右側落板",$E22="內底板", $E22="內左側板",$E22="內右側板", $E22="上前平肢",$E22="上後平肢",$E22="上前立肢",$E22="上後立肢", $E22="下前立肢",$E22="下後立肢",$E22="下前平肢",$E22="下後平肢", $E22="左側落板",$E22="右側落板", $E22="外蓋背板",$E22="台面",$E22="床板",$E22="假門板", $E22="上掀門板",$E22="平掀門板",$E22="下掀門板", $E22="左門板",$E22="右門板", $E22="抽盤",$E22="抽盤抽頭", $E22="上軌道板",$E22="下軌道板",$E22="左軌道板",$E22="右軌道板",$E22="指縫擋板",$E22="左木框滑門",$E22="右木框滑門", $E22="層板",$E22="壁面層板",$E22="桌板",$E22="上封板",$E22="下封板",$E22="左封板",$E22="右封板", $E22="左圓角側板",$E22="右圓角側板",$E22="抽頭",$E22="入柱抽頭",$E22="假抽頭",$E22="背拉桿",$E22="木滑門",$E22="抽屜拉桿" ), "AA", "" ) -> AA | H22: =C10-22 -> -22 | I22: =IF( OR( $E22="右側板",$E22="左側板",$E22="活隔", $E22="天地蓋頂板",$E22="天地蓋底板", $E22="左門板",$E22="右門板", $E22="左側落板",$E22="右側落板", $E22="外蓋背板",$E22="活固隔", $E22="左木框滑門",$E22="右木框滑門", $E22="左鋁框滑門",$E22="右鋁框滑門", $E22="桌板",$E22="台面",$E22="床板",$E22="假門板", $E22="上掀門板",$E22="平掀門板",$E22="下掀門板", $E22="抽盤抽頭",$E22="抽盤",$E22="層板",$E22="壁面層板", $E22="上封板",$E22="下封板",$E22="左封板",$E22="右封板", $E22="抽頭",$E22="踢腳板",$E22="補板",$E22="木滑門" ), "AA", "" ) | J22: 18 | M22: =IFERROR(VLOOKUP(L22,色號!A:B,2,FALSE),"") | N22: =IFERROR(VLOOKUP(M22,色號!B:C,2,FALSE),"") | O22: =IFERROR(VLOOKUP(L22,色號!A:D,4,FALSE),"") | P22: =IF( OR($E22="左門板", $E22="右門板"), "鉸" & IF($F22<=1000, 2, IF($F22<=1800, 3, 4)), IF( $E22="入柱背板", "側", IF( $E22="外蓋背板", "面", IF( AND(COUNTIF($E$14:$E$43,"入柱背板")>0, OR($E22="頂板", $E22="底板")), "面", IF( AND(COUNTIF($E$14:$E$43,"外蓋背板")>0, OR($E22="左側板", $E22="右側板")), "側", IF( AND( COUNTIF($E$14:$E$43,"入柱背板")=0, COUNTIF($E$14:$E$43,"外蓋背板")=0, OR( AND(COUNTIF($E$14:$E$43,"背板")>0, OR($E22="左側板",$E22="右側板",$E22="頂板",$E22="底板",$E22="天地蓋右側板",$E22="天地蓋左側板",$E22="天地蓋底板",$E22="天地蓋頂板")), AND(COUNTIF($E$14:$E$43,"抽底")>0, OR($E22="右抽牆",$E22="左抽牆",$E22="前抽牆",$E22="後抽牆")) ) ), "背板溝", "" ) ) ) ) ) ) | Q22: =IF(OR($E22="天地蓋右側板",$E22="天地蓋左側板"), "側 面", IF(OR($E22="背拉桿",$E22="中立板",$E22="頂板",$E22="底板",$E22="前抽牆",$E22="後抽牆",$E22="內左側落板",$E22="內右側落板",$E22="抽屜拉桿",$E22="立板"), "側", IF(OR($E22="木滑門",$E22="鋁框滑門"), "輪", IF(OR($E22="右側板",$E22="左側板",$E22="右抽牆",$E22="左抽牆",$E22="天地蓋頂板",$E22="天地蓋底板",$E22="內頂板"), "面", IF($E22="固隔","固","") ) ) ) ) -> 固 | R22: =IF( OR($E22="左側板",$E22="右側板",$E22="天地蓋左側板",$E22="天地蓋右側板",$E22="中立板",$E22="立板"), "排","") | T22: =IF($E22="中立板","面開槽？排孔？", IF($E22="木框滑門","前排孔要退喔！", IF(OR($E22="左門板",$E22="右門板",$E22="抽頭"),"把手？", IF(OR($E22="左側板",$E22="右側板",$E22="天地蓋右側板",$E22="天地蓋左側板"),"排孔？","")))) | U22: =IF(E22="","",$L$10) -> 1
A23: =$C$7 -> 0 | C23: =C22+1 -> 1010 | D23: 外部 | E23: 左門板 | G23: =IF( OR( $E23="頂板",$E23="底板",$E23="右側板",$E23="左側板", $E23="天地蓋頂板",$E23="天地蓋底板",$E23="天地蓋右側板",$E23="天地蓋左側板", $E23="前抽牆",$E23="後抽牆",$E23="左抽牆",$E23="右抽牆", $E23="踢腳板",$E23="補板",$E23="固隔",$E23="活隔", $E23="中立板",$E23="中立板(退)",$E23="固隔(退)",$E23="活固隔",$E23="立板", $E23="內頂板",$E23="內左側落板",$E23="內右側落板",$E23="內底板", $E23="內左側板",$E23="內右側板", $E23="上前平肢",$E23="上後平肢",$E23="上前立肢",$E23="上後立肢", $E23="下前立肢",$E23="下後立肢",$E23="下前平肢",$E23="下後平肢", $E23="左側落板",$E23="右側落板", $E23="外蓋背板",$E23="台面",$E23="床板",$E23="假門板", $E23="上掀門板",$E23="平掀門板",$E23="下掀門板", $E23="左門板",$E23="右門板", $E23="抽盤",$E23="抽盤抽頭", $E23="上軌道板",$E23="下軌道板",$E23="左軌道板",$E23="右軌道板",$E23="指縫擋板",$E23="左木框滑門",$E23="右木框滑門", $E23="層板",$E23="壁面層板",$E23="桌板",$E23="上封板",$E23="下封板",$E23="左封板",$E23="右封板", $E23="左圓角側板",$E23="右圓角側板",$E23="抽頭",$E23="入柱抽頭",$E23="假抽頭",$E23="背拉桿",$E23="木滑門",$E23="抽屜拉桿" ), "AA", "" ) -> AA | H23: =C11/2-4 -> -4 | I23: =IF( OR( $E23="右側板",$E23="左側板",$E23="活隔", $E23="天地蓋頂板",$E23="天地蓋底板", $E23="左門板",$E23="右門板", $E23="左側落板",$E23="右側落板", $E23="外蓋背板",$E23="活固隔", $E23="左木框滑門",$E23="右木框滑門", $E23="左鋁框滑門",$E23="右鋁框滑門", $E23="桌板",$E23="台面",$E23="床板",$E23="假門板", $E23="上掀門板",$E23="平掀門板",$E23="下掀門板", $E23="抽盤抽頭",$E23="抽盤",$E23="層板",$E23="壁面層板", $E23="上封板",$E23="下封板",$E23="左封板",$E23="右封板", $E23="抽頭",$E23="踢腳板",$E23="補板",$E23="木滑門" ), "AA", "" ) -> AA | J23: 18 | M23: =IFERROR(VLOOKUP(L23,色號!A:B,2,FALSE),"") | N23: =IFERROR(VLOOKUP(M23,色號!B:C,2,FALSE),"") | O23: =IFERROR(VLOOKUP(L23,色號!A:D,4,FALSE),"") | P23: =IF( OR($E23="左門板", $E23="右門板"), "鉸" & IF($F23<=1000, 2, IF($F23<=1800, 3, 4)), IF( $E23="入柱背板", "側", IF( $E23="外蓋背板", "面", IF( AND(COUNTIF($E$14:$E$43,"入柱背板")>0, OR($E23="頂板", $E23="底板")), "面", IF( AND(COUNTIF($E$14:$E$43,"外蓋背板")>0, OR($E23="左側板", $E23="右側板")), "側", IF( AND( COUNTIF($E$14:$E$43,"入柱背板")=0, COUNTIF($E$14:$E$43,"外蓋背板")=0, OR( AND(COUNTIF($E$14:$E$43,"背板")>0, OR($E23="左側板",$E23="右側板",$E23="頂板",$E23="底板",$E23="天地蓋右側板",$E23="天地蓋左側板",$E23="天地蓋底板",$E23="天地蓋頂板")), AND(COUNTIF($E$14:$E$43,"抽底")>0, OR($E23="右抽牆",$E23="左抽牆",$E23="前抽牆",$E23="後抽牆")) ) ), "背板溝", "" ) ) ) ) ) ) -> 鉸2 | Q23: =IF(OR($E23="天地蓋右側板",$E23="天地蓋左側板"), "側 面", IF(OR($E23="背拉桿",$E23="中立板",$E23="頂板",$E23="底板",$E23="前抽牆",$E23="後抽牆",$E23="內左側落板",$E23="內右側落板",$E23="抽屜拉桿",$E23="立板"), "側", IF(OR($E23="木滑門",$E23="鋁框滑門"), "輪", IF(OR($E23="右側板",$E23="左側板",$E23="右抽牆",$E23="左抽牆",$E23="天地蓋頂板",$E23="天地蓋底板",$E23="內頂板"), "面", IF($E23="固隔","固","") ) ) ) ) | R23: =IF( OR($E23="左側板",$E23="右側板",$E23="天地蓋左側板",$E23="天地蓋右側板",$E23="中立板",$E23="立板"), "排","") | T23: =IF($E23="中立板","面開槽？排孔？", IF($E23="木框滑門","前排孔要退喔！", IF(OR($E23="左門板",$E23="右門板",$E23="抽頭"),"把手？", IF(OR($E23="左側板",$E23="右側板",$E23="天地蓋右側板",$E23="天地蓋左側板"),"排孔？","")))) -> 把手？ | U23: =IF(E23="","",$L$10) -> 1
A24: =$C$7 -> 0 | C24: =C23+1 -> 1011 | D24: 外部 | E24: 右門板 | G24: =IF( OR( $E24="頂板",$E24="底板",$E24="右側板",$E24="左側板", $E24="天地蓋頂板",$E24="天地蓋底板",$E24="天地蓋右側板",$E24="天地蓋左側板", $E24="前抽牆",$E24="後抽牆",$E24="左抽牆",$E24="右抽牆", $E24="踢腳板",$E24="補板",$E24="固隔",$E24="活隔", $E24="中立板",$E24="中立板(退)",$E24="固隔(退)",$E24="活固隔",$E24="立板", $E24="內頂板",$E24="內左側落板",$E24="內右側落板",$E24="內底板", $E24="內左側板",$E24="內右側板", $E24="上前平肢",$E24="上後平肢",$E24="上前立肢",$E24="上後立肢", $E24="下前立肢",$E24="下後立肢",$E24="下前平肢",$E24="下後平肢", $E24="左側落板",$E24="右側落板", $E24="外蓋背板",$E24="台面",$E24="床板",$E24="假門板", $E24="上掀門板",$E24="平掀門板",$E24="下掀門板", $E24="左門板",$E24="右門板", $E24="抽盤",$E24="抽盤抽頭", $E24="上軌道板",$E24="下軌道板",$E24="左軌道板",$E24="右軌道板",$E24="指縫擋板",$E24="左木框滑門",$E24="右木框滑門", $E24="層板",$E24="壁面層板",$E24="桌板",$E24="上封板",$E24="下封板",$E24="左封板",$E24="右封板", $E24="左圓角側板",$E24="右圓角側板",$E24="抽頭",$E24="入柱抽頭",$E24="假抽頭",$E24="背拉桿",$E24="木滑門",$E24="抽屜拉桿" ), "AA", "" ) -> AA | H24: =C11/2-4 -> -4 | I24: =IF( OR( $E24="右側板",$E24="左側板",$E24="活隔", $E24="天地蓋頂板",$E24="天地蓋底板", $E24="左門板",$E24="右門板", $E24="左側落板",$E24="右側落板", $E24="外蓋背板",$E24="活固隔", $E24="左木框滑門",$E24="右木框滑門", $E24="左鋁框滑門",$E24="右鋁框滑門", $E24="桌板",$E24="台面",$E24="床板",$E24="假門板", $E24="上掀門板",$E24="平掀門板",$E24="下掀門板", $E24="抽盤抽頭",$E24="抽盤",$E24="層板",$E24="壁面層板", $E24="上封板",$E24="下封板",$E24="左封板",$E24="右封板", $E24="抽頭",$E24="踢腳板",$E24="補板",$E24="木滑門" ), "AA", "" ) -> AA | J24: 18 | M24: =IFERROR(VLOOKUP(L24,色號!A:B,2,FALSE),"") | N24: =IFERROR(VLOOKUP(M24,色號!B:C,2,FALSE),"") | O24: =IFERROR(VLOOKUP(L24,色號!A:D,4,FALSE),"") | P24: =IF( OR($E24="左門板", $E24="右門板"), "鉸" & IF($F24<=1000, 2, IF($F24<=1800, 3, 4)), IF( $E24="入柱背板", "側", IF( $E24="外蓋背板", "面", IF( AND(COUNTIF($E$14:$E$43,"入柱背板")>0, OR($E24="頂板", $E24="底板")), "面", IF( AND(COUNTIF($E$14:$E$43,"外蓋背板")>0, OR($E24="左側板", $E24="右側板")), "側", IF( AND( COUNTIF($E$14:$E$43,"入柱背板")=0, COUNTIF($E$14:$E$43,"外蓋背板")=0, OR( AND(COUNTIF($E$14:$E$43,"背板")>0, OR($E24="左側板",$E24="右側板",$E24="頂板",$E24="底板",$E24="天地蓋右側板",$E24="天地蓋左側板",$E24="天地蓋底板",$E24="天地蓋頂板")), AND(COUNTIF($E$14:$E$43,"抽底")>0, OR($E24="右抽牆",$E24="左抽牆",$E24="前抽牆",$E24="後抽牆")) ) ), "背板溝", "" ) ) ) ) ) ) -> 鉸2 | T24: =IF($E24="中立板","面開槽？排孔？", IF($E24="木框滑門","前排孔要退喔！", IF(OR($E24="左門板",$E24="右門板",$E24="抽頭"),"把手？", IF(OR($E24="左側板",$E24="右側板",$E24="天地蓋右側板",$E24="天地蓋左側板"),"排孔？","")))) -> 把手？ | U24: =IF(E24="","",$L$10) -> 1
A25: =$C$7 -> 0 | C25: =C24+1 -> 1012 | G25: =IF( OR( $E25="頂板",$E25="底板",$E25="右側板",$E25="左側板", $E25="天地蓋頂板",$E25="天地蓋底板",$E25="天地蓋右側板",$E25="天地蓋左側板", $E25="前抽牆",$E25="後抽牆",$E25="左抽牆",$E25="右抽牆", $E25="踢腳板",$E25="補板",$E25="固隔",$E25="活隔", $E25="中立板",$E25="中立板(退)",$E25="固隔(退)",$E25="活固隔",$E25="立板", $E25="內頂板",$E25="內左側落板",$E25="內右側落板",$E25="內底板", $E25="內左側板",$E25="內右側板", $E25="上前平肢",$E25="上後平肢",$E25="上前立肢",$E25="上後立肢", $E25="下前立肢",$E25="下後立肢",$E25="下前平肢",$E25="下後平肢", $E25="左側落板",$E25="右側落板", $E25="外蓋背板",$E25="台面",$E25="床板",$E25="假門板", $E25="上掀門板",$E25="平掀門板",$E25="下掀門板", $E25="左門板",$E25="右門板", $E25="抽盤",$E25="抽盤抽頭", $E25="上軌道板",$E25="下軌道板",$E25="左軌道板",$E25="右軌道板",$E25="指縫擋板",$E25="左木框滑門",$E25="右木框滑門", $E25="層板",$E25="壁面層板",$E25="桌板",$E25="上封板",$E25="下封板",$E25="左封板",$E25="右封板", $E25="左圓角側板",$E25="右圓角側板",$E25="抽頭",$E25="入柱抽頭",$E25="假抽頭",$E25="背拉桿",$E25="木滑門",$E25="抽屜拉桿" ), "AA", "" ) | I25: =IF( OR( $E25="右側板",$E25="左側板",$E25="活隔", $E25="天地蓋頂板",$E25="天地蓋底板", $E25="左門板",$E25="右門板", $E25="左側落板",$E25="右側落板", $E25="外蓋背板",$E25="活固隔", $E25="左木框滑門",$E25="右木框滑門", $E25="左鋁框滑門",$E25="右鋁框滑門", $E25="桌板",$E25="台面",$E25="床板",$E25="假門板", $E25="上掀門板",$E25="平掀門板",$E25="下掀門板", $E25="抽盤抽頭",$E25="抽盤",$E25="層板",$E25="壁面層板", $E25="上封板",$E25="下封板",$E25="左封板",$E25="右封板", $E25="抽頭",$E25="踢腳板",$E25="補板",$E25="木滑門" ), "AA", "" ) | M25: =IFERROR(VLOOKUP(L25,色號!A:B,2,FALSE),"") | N25: =IFERROR(VLOOKUP(M25,色號!B:C,2,FALSE),"") | O25: =IFERROR(VLOOKUP(L25,色號!A:D,4,FALSE),"") | P25: =IF( OR($E25="左門板", $E25="右門板"), "鉸" & IF($F25<=1000, 2, IF($F25<=1800, 3, 4)), IF( $E25="入柱背板", "側", IF( $E25="外蓋背板", "面", IF( AND(COUNTIF($E$14:$E$43,"入柱背板")>0, OR($E25="頂板", $E25="底板")), "面", IF( AND(COUNTIF($E$14:$E$43,"外蓋背板")>0, OR($E25="左側板", $E25="右側板")), "側", IF( AND( COUNTIF($E$14:$E$43,"入柱背板")=0, COUNTIF($E$14:$E$43,"外蓋背板")=0, OR( AND(COUNTIF($E$14:$E$43,"背板")>0, OR($E25="左側板",$E25="右側板",$E25="頂板",$E25="底板",$E25="天地蓋右側板",$E25="天地蓋左側板",$E25="天地蓋底板",$E25="天地蓋頂板")), AND(COUNTIF($E$14:$E$43,"抽底")>0, OR($E25="右抽牆",$E25="左抽牆",$E25="前抽牆",$E25="後抽牆")) ) ), "背板溝", "" ) ) ) ) ) ) | T25: =IF($E25="中立板","面開槽？排孔？", IF($E25="木框滑門","前排孔要退喔！", IF(OR($E25="左門板",$E25="右門板",$E25="抽頭"),"把手？", IF(OR($E25="左側板",$E25="右側板",$E25="天地蓋右側板",$E25="天地蓋左側板"),"排孔？","")))) | U25: =IF(E25="","",$L$10)
A26: =$C$7 -> 0 | C26: =C25+1 -> 1013 | G26: =IF( OR( $E26="頂板",$E26="底板",$E26="右側板",$E26="左側板", $E26="天地蓋頂板",$E26="天地蓋底板",$E26="天地蓋右側板",$E26="天地蓋左側板", $E26="前抽牆",$E26="後抽牆",$E26="左抽牆",$E26="右抽牆", $E26="踢腳板",$E26="補板",$E26="固隔",$E26="活隔", $E26="中立板",$E26="中立板(退)",$E26="固隔(退)",$E26="活固隔",$E26="立板", $E26="內頂板",$E26="內左側落板",$E26="內右側落板",$E26="內底板", $E26="內左側板",$E26="內右側板", $E26="上前平肢",$E26="上後平肢",$E26="上前立肢",$E26="上後立肢", $E26="下前立肢",$E26="下後立肢",$E26="下前平肢",$E26="下後平肢", $E26="左側落板",$E26="右側落板", $E26="外蓋背板",$E26="台面",$E26="床板",$E26="假門板", $E26="上掀門板",$E26="平掀門板",$E26="下掀門板", $E26="左門板",$E26="右門板", $E26="抽盤",$E26="抽盤抽頭", $E26="上軌道板",$E26="下軌道板",$E26="左軌道板",$E26="右軌道板",$E26="指縫擋板",$E26="左木框滑門",$E26="右木框滑門", $E26="層板",$E26="壁面層板",$E26="桌板",$E26="上封板",$E26="下封板",$E26="左封板",$E26="右封板", $E26="左圓角側板",$E26="右圓角側板",$E26="抽頭",$E26="入柱抽頭",$E26="假抽頭",$E26="背拉桿",$E26="木滑門",$E26="抽屜拉桿" ), "AA", "" ) | I26: =IF( OR( $E26="右側板",$E26="左側板",$E26="活隔", $E26="天地蓋頂板",$E26="天地蓋底板", $E26="左門板",$E26="右門板", $E26="左側落板",$E26="右側落板", $E26="外蓋背板",$E26="活固隔", $E26="左木框滑門",$E26="右木框滑門", $E26="左鋁框滑門",$E26="右鋁框滑門", $E26="桌板",$E26="台面",$E26="床板",$E26="假門板", $E26="上掀門板",$E26="平掀門板",$E26="下掀門板", $E26="抽盤抽頭",$E26="抽盤",$E26="層板",$E26="壁面層板", $E26="上封板",$E26="下封板",$E26="左封板",$E26="右封板", $E26="抽頭",$E26="踢腳板",$E26="補板",$E26="木滑門" ), "AA", "" ) | M26: =IFERROR(VLOOKUP(L26,色號!A:B,2,FALSE),"") | N26: =IFERROR(VLOOKUP(M26,色號!B:C,2,FALSE),"") | O26: =IFERROR(VLOOKUP(L26,色號!A:D,4,FALSE),"") | P26: =IF( OR($E26="左門板", $E26="右門板"), "鉸" & IF($F26<=1000, 2, IF($F26<=1800, 3, 4)), IF( $E26="入柱背板", "側", IF( $E26="外蓋背板", "面", IF( AND(COUNTIF($E$14:$E$43,"入柱背板")>0, OR($E26="頂板", $E26="底板")), "面", IF( AND(COUNTIF($E$14:$E$43,"外蓋背板")>0, OR($E26="左側板", $E26="右側板")), "側", IF( AND( COUNTIF($E$14:$E$43,"入柱背板")=0, COUNTIF($E$14:$E$43,"外蓋背板")=0, OR( AND(COUNTIF($E$14:$E$43,"背板")>0, OR($E26="左側板",$E26="右側板",$E26="頂板",$E26="底板",$E26="天地蓋右側板",$E26="天地蓋左側板",$E26="天地蓋底板",$E26="天地蓋頂板")), AND(COUNTIF($E$14:$E$43,"抽底")>0, OR($E26="右抽牆",$E26="左抽牆",$E26="前抽牆",$E26="後抽牆")) ) ), "背板溝", "" ) ) ) ) ) ) | T26: =IF($E26="中立板","面開槽？排孔？", IF($E26="木框滑門","前排孔要退喔！", IF(OR($E26="左門板",$E26="右門板",$E26="抽頭"),"把手？", IF(OR($E26="左側板",$E26="右側板",$E26="天地蓋右側板",$E26="天地蓋左側板"),"排孔？","")))) | U26: =IF(E26="","",$L$10)
A27: =$C$7 -> 0 | C27: =C26+1 -> 1014 | G27: =IF( OR( $E27="頂板",$E27="底板",$E27="右側板",$E27="左側板", $E27="天地蓋頂板",$E27="天地蓋底板",$E27="天地蓋右側板",$E27="天地蓋左側板", $E27="前抽牆",$E27="後抽牆",$E27="左抽牆",$E27="右抽牆", $E27="踢腳板",$E27="補板",$E27="固隔",$E27="活隔", $E27="中立板",$E27="中立板(退)",$E27="固隔(退)",$E27="活固隔",$E27="立板", $E27="內頂板",$E27="內左側落板",$E27="內右側落板",$E27="內底板", $E27="內左側板",$E27="內右側板", $E27="上前平肢",$E27="上後平肢",$E27="上前立肢",$E27="上後立肢", $E27="下前立肢",$E27="下後立肢",$E27="下前平肢",$E27="下後平肢", $E27="左側落板",$E27="右側落板", $E27="外蓋背板",$E27="台面",$E27="床板",$E27="假門板", $E27="上掀門板",$E27="平掀門板",$E27="下掀門板", $E27="左門板",$E27="右門板", $E27="抽盤",$E27="抽盤抽頭", $E27="上軌道板",$E27="下軌道板",$E27="左軌道板",$E27="右軌道板",$E27="指縫擋板",$E27="左木框滑門",$E27="右木框滑門", $E27="層板",$E27="壁面層板",$E27="桌板",$E27="上封板",$E27="下封板",$E27="左封板",$E27="右封板", $E27="左圓角側板",$E27="右圓角側板",$E27="抽頭",$E27="入柱抽頭",$E27="假抽頭",$E27="背拉桿",$E27="木滑門",$E27="抽屜拉桿" ), "AA", "" ) | I27: =IF( OR( $E27="右側板",$E27="左側板",$E27="活隔", $E27="天地蓋頂板",$E27="天地蓋底板", $E27="左門板",$E27="右門板", $E27="左側落板",$E27="右側落板", $E27="外蓋背板",$E27="活固隔", $E27="左木框滑門",$E27="右木框滑門", $E27="左鋁框滑門",$E27="右鋁框滑門", $E27="桌板",$E27="台面",$E27="床板",$E27="假門板", $E27="上掀門板",$E27="平掀門板",$E27="下掀門板", $E27="抽盤抽頭",$E27="抽盤",$E27="層板",$E27="壁面層板", $E27="上封板",$E27="下封板",$E27="左封板",$E27="右封板", $E27="抽頭",$E27="踢腳板",$E27="補板",$E27="木滑門" ), "AA", "" ) | M27: =IFERROR(VLOOKUP(L27,色號!A:B,2,FALSE),"") | N27: =IFERROR(VLOOKUP(M27,色號!B:C,2,FALSE),"") | O27: =IFERROR(VLOOKUP(L27,色號!A:D,4,FALSE),"") | P27: =IF( OR($E27="左門板", $E27="右門板"), "鉸" & IF($F27<=1000, 2, IF($F27<=1800, 3, 4)), IF( $E27="入柱背板", "側", IF( $E27="外蓋背板", "面", IF( AND(COUNTIF($E$14:$E$43,"入柱背板")>0, OR($E27="頂板", $E27="底板")), "面", IF( AND(COUNTIF($E$14:$E$43,"外蓋背板")>0, OR($E27="左側板", $E27="右側板")), "側", IF( AND( COUNTIF($E$14:$E$43,"入柱背板")=0, COUNTIF($E$14:$E$43,"外蓋背板")=0, OR( AND(COUNTIF($E$14:$E$43,"背板")>0, OR($E27="左側板",$E27="右側板",$E27="頂板",$E27="底板",$E27="天地蓋右側板",$E27="天地蓋左側板",$E27="天地蓋底板",$E27="天地蓋頂板")), AND(COUNTIF($E$14:$E$43,"抽底")>0, OR($E27="右抽牆",$E27="左抽牆",$E27="前抽牆",$E27="後抽牆")) ) ), "背板溝", "" ) ) ) ) ) ) | T27: =IF($E27="中立板","面開槽？排孔？", IF($E27="木框滑門","前排孔要退喔！", IF(OR($E27="左門板",$E27="右門板",$E27="抽頭"),"把手？", IF(OR($E27="左側板",$E27="右側板",$E27="天地蓋右側板",$E27="天地蓋左側板"),"排孔？","")))) | U27: =IF(E27="","",$L$10)
